Workbook

Sheet Sun 2
A1: SUN 2 SYLLABUS
A2: DATES | B2: LESSONS | C2: UNITS | D2: Student's book PAGES | E2: CONTENTS | J2: Classroom materials
E3: Vocabulary | F3: Grammar/Structures | G3: Lesson target | H3: Homework
H4: Activity book pages (Assigned by teachers) | I4: E-learning (Assigned by CM)
A5: TERM A (UNIT 1 - 6)
B6: LESSON 1 | C6: UNIT 1 HELLO AGAIN! | D6: 4 | E6: - Star's family members: Mr. Star, Mrs. Star, Suzy, Simon, Stella, Maskman, Monty, Grandma Star, Grandpa Star | F6: - Who is this ? - Hello! I'm …. - This is ….. | G6: Introduce students name and remember the Star's family members | H6: 4 | I6: Vocabulary 2
B7: LESSON 2 | C7: UNIT 1 HELLO AGAIN! | D7: 5 | E7: - Review characters - Numbers: 1-10 | F7: - What's your name? - How old are you? - Who's he/she? | G7: Introduce the student's age and practice using He and She. | H7: 5 | I7: Grammar 1
B8: LESSON 3 | C8: UNIT 1 HELLO AGAIN! | D8: 6-7 | E8: - Aphabet - Colors: pink, green, grey, orange, red, brown, white, blue, yellow, black, purple. | F8: - What letter is it? + It's letter….. - What color is it? + It's …… - Can you spell "PURPLE" ? | G8: - Students review the alphabet and colors - Students can spell their names and vocabulary. | H8: 7 | I8: Vocabulary 1 & 3 Grammar 2
B9: LESSON 4 | C9: UNIT 1 HELLO AGAIN! | D9: 8-9 | E9: - Pronunciation: long vowel sound "ay" - Preposition: On, in, under - Listen to the story - Watching videos: + Skipping game | F9: - /ay/ - snake, play, game - /ay/ - Four snakes are playing games! - The pencil is under the chair. | G9: - Student learn some words start with /ay/ sound in "Monty Phonics". Encourage students to know more words. - With the story, make 3 questions so students will answer them after the story - With videos, students can understand and play the game. | H9: 8-9 | I9: Reading 1 & 2 Grammar 3
B10: LESSON 5 | C10: UNIT 1 HELLO AGAIN! | D10: REVIEW | E10: - Review Unit 1 (vocabulary and structures) - Unit 1 test - Unit 1 Speaking video (link) | F10: - Who is this ? - Hello! I'm …. - This is ….. - What letter is it? + It's letter….. - What color is it? + It's …… - Can you spell "PURPLE" ? | G10: - Students review all vocabulary and structures | H10: Unit 1 Home booklet | I10: Game 1 and 2
B11: LESSON 6 | C11: UNIT 2 BACK TO SCHOOL | D11: 10-11 | E11: - School things: Board, bookcase, ruler, cupboard, teacher, desk. - Numbers: 11 to 20 | F11: - What is it ? It's a green cupboard. - How many desks are there? There are 11 desks. | G11: - Students remember the words - Students can use adjective to answer. - Students can use grammar correctly. | H11: 10-11 | I11: Vocabulary 2&3
B12: LESSON 7 | C12: UNIT 2 BACK TO SCHOOL | D12: 12-13 | E12: - Review school things - Reading: Meera's classroom - Sing a song | F12: - How many …. are there? There is/are….. | G12: - Students review the vocabulary - Students practice the grammar in speaking and exercises. - Students can sing a song together | H12: 12-13 | I12: Vocabulary 1 Grammar 1
B13: LESSON 8 | C13: UNIT 2 BACK TO SCHOOL | D13: 14-15 | E13: - Pronunciation: Long vowel sound "ee" - Listen to the story - Watching video: The hokey cokey | F13: - /ee/ - three, teacher, tree Three teachers sleeping in a tree - Review there is/are | G13: - Student learn some words start with /ee/ sound in "Monty's phonics". - With the story, make 3 questions so students answer them after the story - With the videos, students can understand and play the game. | H13: 14-15 | I13: Grammar 2 Reading 1
B14: LESSON 9 | C14: UNIT 2 BACK TO SCHOOL | D14: 16-17 | E14: - Marie's math: Block graphs - Fruit: oranges, bananas, apples, pears, pineapples, lemons - Trevor's value: Be polite - Project: Make a block graph | F14: - Can you … please? Yes, of course. - Can you come in? Yes, come in. | G14: - Students can use "there is/are" to talk about the block graph - Understnd the value of lesson | H14: 16-17 | I14: Grammar 3 Reading 2
B15: LESSON 10 | C15: UNIT 2 BACK TO SCHOOL | D15: REVIEW | E15: - Review Unit 2 (vocabulary and structures) - Unit 2 test - Unit 2 Speaking video (link) | F15: - What is it ? It's a green cupboard. - How many …. are there? There is/are….. | G15: - Students review all vocabulary and structures | H15: Unit 2 Home booklet | I15: Game 1 and 2 | J15: Story Fun 2 Our Funny home
B16: LESSON 11 | C16: UNIT 3 PLAY TIME! | D16: 18 | E16: - Toys: kite, watch, lorry, alien, robot, camera, computer game | F16: - What is it? It's a…. - Do you like….? Yes, I do./ No, I don't. | G16: Students understand the topic and remember the words | H16: 18 | I16: Vocabulary 3
B17: LESSON 12 | C17: UNIT 3 PLAY TIME! | D17: 19 | E17: - Review Toys - Review numbers: 11 to 20 | F17: - This is a robot. - These are dolls. | G17: Students review the words and use grammar correctly. | H17: 19 | I17: Vocabulary 1 Grammar 1
B18: LESSON 13 | C18: UNIT 3 PLAY TIME! | D18: 20-21 | E18: - Review Toys - Sing a song | F18: - Whose is this? It's ….'s. - Whose are these? They are …'s. | G18: - Student can use grammar correctly. - Students can sing a song together | H18: 20-21 | I18: Vocabulary 2 Grammar 2
B19: LESSON 14 | C19: UNIT 3 PLAY TIME! | D19: 22-23 | E19: - Pronunciation: Long vowel sound "ai" - Listen to the story - Watching videos: + What's the time, Mr. Wolf? | F19: /ai/ - fly, five, kite I'm flying my five white kites. | G19: - Student learn some words start with /ai/ sound in "Monty's phonics". - With the story, make 3 questions so students answer them after the story - With videos, students can understand and play the game. | H19: 22-23 | I19: Grammar 3 Reading 1 & 2
B20: LESSON 15 | C20: UNIT 3 PLAY TIME! | D20: REVIEW | E20: - Review Unit 3 (vocabulary and structures) - Unit 3 test - Unit 3 Speaking video (link) | F20: - This is a robot. - These are dolls. - Whose is this? It's ….'s. - Whose are these? They are …'s. | G20: - Students review all vocabulary and structures | H20: Unit 3 Home booklet | I20: Game 1 and 2
B21: LESSON 16 | C21: UNIT 4 AT HOME | D21: 24-25 | E21: - Things in a house: mirror, mat, sofa, phone, lamp, clock. - Review rooms in a house. | F21: - What is it? It's a... - There is…..in the living room. | G21: Students remember the words and use them with structure correctly. | H21: 24-25 | I21: Vocabulary 2
B22: LESSON 17 | C22: UNIT 4 AT HOME | D22: 26-27 | E22: - Review things in a house - Sing a song - Possessive pronouns: Mine, yours, his, hers | F22: - Are those blue socks yours? + Thery are mine/yours. + They are not mine/yours. - Is that yellow skirt yours? + It's mine/yours. + It's not mine/yours. - Which bag is yours? + The red one's mine. | G22: - Student can use grammar correctly - Students can sing a song together | H22: 26-27 | I22: Vocabulary 1 Grammar 3
B23: LESSON 18 | C23: UNIT 4 AT HOME | D23: 28-29 | E23: - Pronunciation: Long vowel sound: "oa/oe/ow" - Listen to the story | F23: /oe/ - phone /ow/ - yellow /oa/ - boat A phone in a yellow boat! - Review yours/mine. | G23: - Student learn some words start with /oe/, /ow/ and /oa/ sounds in "Monty's phonics". - With the story, make 3 questions so students answer them after the story - With videos, students can understand how to decorate a box | H23: 28-29 | I23: Vocabulary 3 Grammar 2 & 3
B24: LESSON 19 | C24: UNIT 4 AT HOME | D24: 30-31 | E24: - Marie's art: Origami - Trevor values: Re-use and recycle - New words: bottles, flowerpot, keyboard, plastic bags - Project: Make a toys by origami. | F24: - What's this? It's a….. - What's it made from? It's made from …. | G24: - Students understand the topic (orgiami) - Understnd the value of re-use and recycle. - Finish the project in class. | H24: 30-31 | I24: Grammar 1 Reading 1 & 2
B25: LESSON 20 | C25: UNIT 4 AT HOME | D25: REVIEW | E25: - Review Unit 4 (vocabulary and structures) - Unit 4 test - Unit 4 Speaking video (link) | F25: - Are those blue socks yours? + It's mine/yours. + It's not mine/yours. - Which bag is yours? + The red one's mine. | G25: - Students review all vocabulary and structures | H25: Unit 4 Home booklet | I25: Game 1 and 2 | J25: Story Fun 2 Jill's jellyfish
B26: LESSON 21 | C26: UNIT 5 MEET MY FAMILY | D26: 34 | E26: - Family members: mum, dad, baby, grandma, baby, cousin | F26: - Who is this? He/She is.... | G26: Students understand the topic and remember the words | H26: 34 | I26: Vocabulary 3
B27: LESSON 22 | C27: UNIT 5 MEET MY FAMILY | D27: 35 | E27: - Review family members - Learn about family tree | F27: - She is Lenny's mother. - He is Lenny's father. | G27: Students review the vocabular and understand the family tree | H27: 35 | I27: Vocabulary 1 Grammar 2
B28: LESSON 23 | C28: UNIT 5 MEET MY FAMILY | D28: 36-37 | E28: - Verb: getting, throwing, catching, flying, talking, jumping, sitting, hitting, cleaning, running, kicking, sleeping - Sing a song | F28: - What's he/she doing? He/She is getting/flying/... | G28: - Students remember the verb. - Students can use grammar to talk about people in the picture correctly. - Students can sing a song together. | H28: 36-37 | I28: Vocabulary 2 Grammar 3
B29: LESSON 24 | C29: UNIT 5 MEET MY FAMILY | D29: 38-39 | E29: - Pronunciation: long vowel sound "oo" - Watch a story - Watching videos: + At the sports centre | F29: - Blue - Sue - Ruler - Sue's got a big blue ruler. | G29: - Student learn some words start with /oo/ sounds in "Monty's phonics". - With the story, make 3 questions so students answer them after the story - With videos, students can understand the topic | H29: 38-39 | I29: Grammar 1 Reading 1 & 2
B30: LESSON 25 | C30: UNIT 5 MEET MY FAMILY | D30: REVIEW | E30: - Review Unit 5 (vocabulary and structures) - Unit 5 test - Unit 5 Speaking video (link) | F30: - She is Lenny's mother. - He is Lenny's father. - What's he/she doing? He/She is getting/flying/... | G30: - Students review all vocabulary and structures | H30: Unit 5 Home booklet | I30: Game 1 and 2
B31: LESSON 26 | C31: UNIT 6 DINNER TIME | D31: 40-41 | E31: - Food: Bread, water, milk, juice, chicken, eggs, chips, rice - Day times: Morning, lunchtime, afternoon, evening - Meals: Breakfast, lunch, dinner - Sing a song activity | G31: - Students remember the words - Students know how to say the meal in different time of a day (breakfast for morning time, dinner for evening time,...) - Students can sing a song together. | H31: 40-41 | I31: Vocabulary 2 Vocabulary 3
B32: LESSON 27 | C32: UNIT 6 DINNER TIME | D32: 42-43 | E32: - Review food, day times and meals - Reading: A day of Alex | F32: Can I have some...., please? - Here you are. - Sorry, I don't have. | G32: - Students can use structure to order the food they want. - For reading part, students can write a short paragraph about their days | H32: 42-43 | I32: Grammar 1 & 2
B33: LESSON 28 | C33: UNIT 6 DINNER TIME | D33: 44-45 | E33: - Pronunciation: /ch/ - Watch the story | F33: /ch/-/ch/-chicken, kitchen The chickens are cooking in the kitchen. | G33: - Student learn some words start with /oo/ sounds in "Monty's phonics". - With the story, make 3 questions so students answer them after the story - With videos, students can understand the topic | H33: 44-45 | I33: Reading 1 & 2
B34: LESSON 29 | C34: UNIT 6 DINNER TIME | D34: 46-47 | E34: - Marie's science: Food + Animals, meat, plants, trees - Trevor's value: Eat good food - Project: Make a food poster | F34: - Eggs are from animals. - Carrots are from plants | G34: - Students understand different types of food. - Students understand the value of the lesson. - Students finish the project and talk about it. | H34: 46-47 | I34: Vocabulary 1 Grammar 3
B35: LESSON 30 | C35: UNIT 6 DINNER TIME | D35: REVIEW | E35: - Review Unit 6 (vocabulary and structures) - Unit 6 test - Unit 6 Speaking video (link) | F35: - What's this? It's ... - What are these? They're .... - I have breakfast in the morning. Can I have some...., please? - Here you are. - Sorry, I don't have. | G35: - Students review all vocabulary and structures | H35: Unit 6 Home booklet | I35: Game 1 and 2 | J35: Story Fun 2 Uncle Fred and me
B36: LESSON 31 | C36: REVIEW | D36: 4-17 | E36: Review all vocabularies of Unit 1 and 2 | F36: - Who is this ? - Hello! I'm …. - This is ….. - What letter is it? + It's letter….. - What color is it? + It's …… - Can you spell "PURPLE" ? - What is it ? It's a green cupboard. - How many …. are there? There is/are….. | G36: - Students review the lesson contents of Unit 1 & 2 | H36: HomeFun 2 Topic 1 Animals Topic 2 The body and face | I36: Unit 1-2 Game 1 & 2 | J36: link
B37: LESSON 32 | C37: REVIEW | D37: 18-31 | E37: Review all vocabularies of Unit 3 and 4 | F37: - This is a robot. - These are dolls. - Whose is this? It's ….'s. - Whose are these? They are …'s. - Are those blue socks yours? + It's mine/yours. + It's not mine/yours. - Which bag is yours? + The red one's mine. | G37: - Students review the lesson contents of Unit 3 & 4 | H37: HomeFun 2 Topic 3 & 4 Clothes and Colours | I37: Unit 3-4 Game 1 & 2 | J37: link
B38: LESSON 33 | C38: REVIEW | D38: 34-47 | E38: Review all vocabularies of Unit 5 and 6 | F38: - She is Lenny's mother. - He is Lenny's father. - What's he/she doing? He/She is getting/flying/... - What's this? It's ... - What are these? They're .... - I have breakfast in the morning. Can I have some...., please? - Here you are. - Sorry, I don't have. | G38: - Students review the lesson contents of Unit 5 & 6 | H38: HomeFun 2 Topic 5 Family and friends Topic 6 Food and Drink | I38: Unit 5-6 Game 1 & 2 | J38: link
B39: LESSON 34 | C39: MID-TERM | D39: TEST | E39: MID-TERM TEST - READING, WRITING AND SPEAKING (Speaking test for students whose finish the reading and writing test early. Teachers prepare extra materials for students) | J39: Fun for Starter (21-25)
B40: LESSON 35 | C40: MID-TERM | D40: TEST | E40: MID-TERM SPEAKING TEST (Speaking test for students whose aren't finished) | J40: Fun for Starter (26-30)
...

Sheet Syllabus
A1: SUN - HAPPY TREE 2 SYLLABUS
A2: DATES | B2: LESSONS | C2: UNITS | D2: Student's book PAGES | E2: CONTENTS
E3: Vocabulary | F3: Grammar/Structures | G3: Lesson target | H3: Homework
H4: Activity book | I4: Handbook | J4: E-learning (Assigned by CM)
B5: LESSON 1 | C5: UNIT 1 HELLO AGAIN! | D5: 4 | E5: - Star's family members: Mr. Star, Mrs. Star, Suzy, Simon, Stella, Maskman, Monty, Grandma Star, Grandpa Star | F5: - Who is this ? - Hello! I'm …. - This is ….. | G5: Introduce students name and remember the Star's family members | H5: 4 | I5: =B5 -> LESSON 1 | J5: Vocabulary 2
B6: LESSON 2 | C6: UNIT 1 HELLO AGAIN! | D6: 5 | E6: - Review characters - Numbers: 1-10 | F6: - What's your name? - How old are you? - Who's he/she? | G6: Introduce the student's age and practice using He and She. | H6: 5 | I6: =B6 -> LESSON 2 | J6: Grammar 1
B7: LESSON 3 | C7: UNIT 1 HELLO AGAIN! + SPEAKING PROJECT | D7: 6-7 | E7: - Aphabet - Colors: pink, green, grey, orange, red, brown, white, blue, yellow, black, purple. - Speaking Project: Sun 2 Unit 1 Speaking Project | F7: - What letter is it? + It's letter….. - What color is it? + It's …… - Can you spell "PURPLE" ? | G7: - Students review the alphabet and colors - Students can spell their names and vocabulary. | H7: =D7 -> 6-7 | I7: =B7 -> LESSON 3 | J7: Vocabulary 1 & 3 Grammar 2
B8: LESSON 4 | C8: UNIT 1 HELLO AGAIN! | D8: 8-9 | E8: - Sounds and spelling: wh - Listen to the story | F8: - /wh/ - /wh/ - whale Where's the white whale? Next to the wheel | G8: - Student learn some words start with /ay/ sound in "Monty Phonics". Encourage students to know more words. - With the story, make 3 questions so students will answer them after the story - With videos, students can understand and play the game. | H8: 8-9 | I8: =B8 -> LESSON 4 | J8: Reading 1 & 2 Grammar 3 | L8: x
B9: LESSON 5 | C9: UNIT 1 HELLO AGAIN! | D9: REVIEW & TEST | E9: - Review Unit 1 (vocabulary and structures) - Unit 1 paper test | F9: - Who is this ? - Hello! I'm …. - This is ….. - What letter is it? + It's letter….. - What color is it? + It's …… - Can you spell "PURPLE" ? | G9: - Students review all vocabulary and structures | H9: No homework | I9: =B9 -> LESSON 5 | J9: Game 1 and 2
B10: LESSON 6 | C10: UNIT 2 BACK TO SCHOOL | D10: 10-11 | E10: - School things: Board, bookcase, ruler, cupboard, teacher, desk. - Numbers: 11 to 20 | F10: - What is it ? It's a green cupboard. - How many desks are there? There are 11 desks. | G10: - Students remember the words - Students can use adjective to answer. - Students can use grammar correctly. | H10: 10-11 | I10: =B10 -> LESSON 6 | J10: Vocabulary 2&3
B11: LESSON 7 | C11: UNIT 2 BACK TO SCHOOL | D11: 12-13 | E11: - Review school things and numbers - Reading: Meera's classroom - Sing a song | F11: - How many …. are there? There is/are….. | G11: - Students review the vocabulary - Students practice the grammar in speaking and exercises. - Students can sing a song together | H11: 12-13 | I11: =B11 -> LESSON 7 | J11: Vocabulary 1 Grammar 1
B12: LESSON 8 | C12: UNIT 2 BACK TO SCHOOL + SPEAKING PROJECT | D12: 14-15 | E12: - Sounds and spelling: Long vowel sound "ee" - Listen and watch the story - Speaking Project: Sun 2 Unit 2 Speaking Project | F12: - /ee/ - bee How many bees can you see? Seventeen bees in the tree! - Review there is/are | G12: - Student learn some words start with /ee/ sound in "Monty's phonics". - With the story, make 3 questions so students answer them after the story - With the videos, students can understand and play the game. | H12: 14-15 | I12: =B12 -> LESSON 8 | J12: Grammar 2 Reading 1 | L12: x
B13: LESSON 9 | C13: UNIT 2 BACK TO SCHOOL | D13: 16-17 | E13: - Marie's math: Block graphs - Bar chart and pictogram - Trevor's value: Be polite | F13: - Can you … please? Yes, of course. - Can you come in? Yes, come in. | G13: - Students can use "there is/are" to talk about the block graph - Understnd the value of lesson | H13: 16-17 | I13: =B13 -> LESSON 9 | J13: Grammar 3 Reading 2
B14: LESSON 10 | C14: UNIT 2 BACK TO SCHOOL | D14: REVIEW & TEST | E14: - Review Unit 2 (vocabulary and structures) - Unit 2 paper test - Extra book: Story Fun 2 - Our Funny Home (Teachers ask students to open Handbook lesson 10) | F14: - What is it ? It's a green cupboard. - How many …. are there? There is/are….. | G14: - Students review all vocabulary and structures | H14: No homework | I14: =B14 -> LESSON 10 | J14: Game 1 and 2
B15: LESSON 11 | C15: UNIT 3 PLAY TIME! | D15: 18 | E15: - Toys: kite, watch, lorry, alien, robot, camera, computer game | F15: - What is it? It's a…. - Do you like….? Yes, I do./ No, I don't. | G15: Students understand the topic and remember the words | H15: 18 | I15: =B15 -> LESSON 11 | J15: Vocabulary 3
B16: LESSON 12 | C16: UNIT 3 PLAY TIME! | D16: 19 | E16: - Review Toys - Review numbers: 11 to 20 | F16: - This is a robot. - These are dolls. | G16: Students review the words and use grammar correctly. | H16: 19 | I16: =B16 -> LESSON 12 | J16: Vocabulary 1 Grammar 1
B17: LESSON 13 | C17: UNIT 3 PLAY TIME! + SPEAKING PROJECT | D17: 20-21 | E17: - Review Toys - Sing a song - Speaking Project: Sun 2 Unit 3 Speaking Project | F17: - Whose is this? It's ….'s. - Whose are these? They are …'s. | G17: - Student can use grammar correctly. - Students can sing a song together | H17: 20-21 | I17: =B17 -> LESSON 13 | J17: Vocabulary 2 Grammar 2
B18: LESSON 14 | C18: UNIT 3 PLAY TIME! | D18: 22-23 | E18: - Sounds and spelling: i-e - Listen and watch the story | F18: - i-e: kite - Hide the five kites and ride the white bike! | G18: - Student learn some words start with /ai/ sound in "Monty's phonics". - With the story, make 3 questions so students answer them after the story - With videos, students can understand and play the game. | H18: 22-23 | I18: =B18 -> LESSON 14 | J18: Grammar 3 Reading 1 & 2 | L18: x
B19: LESSON 15 | C19: UNIT 3 PLAY TIME! | D19: REVIEW & TEST | E19: - Review Unit 3 (vocabulary and structures) - Unit 3 paper test | F19: - This is a robot. - These are dolls. - Whose is this? It's ….'s. - Whose are these? They are …'s. | G19: - Students review all vocabulary and structures | H19: No homework | I19: =B19 -> LESSON 15 | J19: Game 1 and 2
B20: LESSON 16 | C20: UNIT 4 AT HOME | D20: 24-25 | E20: - Things in a house: mirror, mat, sofa, phone, lamp, clock. - Review rooms in a house. | F20: - What is it? It's a... - There is…..in the living room. | G20: Students remember the words and use them with structure correctly. | H20: 24-25 | I20: =B20 -> LESSON 16 | J20: Vocabulary 2
B21: LESSON 17 | C21: UNIT 4 AT HOME | D21: 26-27 | E21: - Review things in a house - Sing a song - Possessive pronouns: Mine, yours, his, hers | F21: - Are those blue socks yours? + Thery are mine/yours. + They are not mine/yours. - Is that yellow skirt yours? + It's mine/yours. + It's not mine/yours. - Which bag is yours? + The red one's mine. | G21: - Student can use grammar correctly - Students can sing a song together | H21: 26-27 | I21: =B21 -> LESSON 17 | J21: Vocabulary 1 Grammar 3
B22: LESSON 18 | C22: UNIT 4 AT HOME + SPEAKING PROJECT | D22: 28-29 | E22: - Sounds and spelling: -se - Listen to the story - Speaking Project: Sun 2 Unit 4 Speaking Project | F22: - -se: nose Whose are those noses? Look and choose! - Review yours/mine. | G22: - Student learn some words start with /oe/, /ow/ and /oa/ sounds in "Monty's phonics". - With the story, make 3 questions so students answer them after the story - With videos, students can understand how to decorate a box | H22: 28-29 | I22: =B22 -> LESSON 18 | J22: Vocabulary 3 Grammar 2 & 3 | L22: x
B23: LESSON 19 | C23: UNIT 4 AT HOME | D23: 30-31 | E23: - Marie's art: Origami - Trevor values: Re-use and recycle - New words: box, bird, heart, star, flower | F23: - What's this? It's a….. - What's it made from? It's made from …. | G23: - Students understand the topic (orgiami) - Understnd the value of re-use and recycle. - Finish the project in class. | H23: 30-31 | I23: =B23 -> LESSON 19 | J23: Grammar 1 Reading 1 & 2 | L23: x
B24: LESSON 20 | C24: UNIT 4 AT HOME | D24: REVIEW & TEST | E24: - Review Unit 4 (vocabulary and structures) - Unit 4 paper test - Extra book: Story Fun 2 - Jill's jellyfish (Teachers ask students to open Handbook lesson 20) | F24: - Are those blue socks yours? + It's mine/yours. + It's not mine/yours. - Which bag is yours? + The red one's mine. | G24: - Students review all vocabulary and structures | H24: No homework | I24: =B24 -> LESSON 20 | J24: Game 1 and 2
B25: LESSON 21 | C25: UNIT 5 MEET MY FAMILY | D25: 34 | E25: - Family members: mum, dad, baby, grandma, baby, cousin | F25: - Who is this? He/She is.... | G25: Students understand the topic and remember the words | H25: 34 | I25: =B25 -> LESSON 21 | J25: Vocabulary 3
B26: LESSON 22 | C26: UNIT 5 MEET MY FAMILY | D26: 35 | E26: - Review family members - Learn about family tree | F26: - She is Lenny's mother. - He is Lenny's father. | G26: Students review the vocabular and understand the family tree | H26: 35 | I26: =B26 -> LESSON 22 | J26: Vocabulary 1 Grammar 2
B27: LESSON 23 | C27: UNIT 5 MEET MY FAMILY + SPEAKING PROJECT | D27: 36-37 | E27: - Verb: getting, throwing, catching, flying, talking, jumping, sitting, hitting, cleaning, running, kicking, sleeping - Sing a song - Speaking Project: Sun 2 Unit 5 Speaking Project | F27: - What's he/she doing? He/She is getting/flying/... | G27: - Students remember the verb. - Students can use grammar to talk about people in the picture correctly. - Students can sing a song together. | H27: 36-37 | I27: =B27 -> LESSON 23 | J27: Vocabulary 2 Grammar 3
B28: LESSON 24 | C28: UNIT 5 MEET MY FAMILY | D28: 38-39 | E28: - Sounds and spelling: c, ck and k - Listen and watch a story | F28: - Look, crocodile! - A cat in a coat is taking your cup! - Review present continuous | G28: - Student learn some words start with /oo/ sounds in "Monty's phonics". - With the story, make 3 questions so students answer them after the story - With videos, students can understand the topic | H28: 38-39 | I28: =B28 -> LESSON 24 | J28: Grammar 1 Reading 1 & 2 | L28: x
B29: LESSON 25 | C29: UNIT 5 MEET MY FAMILY | D29: REVIEW & TEST | E29: - Review Unit 5 (vocabulary and structures) - Unit 5 paper test | F29: - She is Lenny's mother. - He is Lenny's father. - What's he/she doing? He/She is getting/flying/... | G29: - Students review all vocabulary and structures | H29: No homework | I29: =B29 -> LESSON 25 | J29: Game 1 and 2
B30: LESSON 26 | C30: UNIT 6 DINNER TIME | D30: 40-41 | E30: - Food: Bread, water, milk, juice, chicken, eggs, chips, rice - Day times: Morning, lunchtime, afternoon, evening - Meals: Breakfast, lunch, dinner - Sing a song activity | F30: What is it? It's ... What can you see in the kitchen? I can see (bread). | G30: - Students remember the words - Students know how to say the meal in different time of a day (breakfast for morning time, dinner for evening time,...) - Students can sing a song together. | H30: 40-41 | I30: =B30 -> LESSON 26 | J30: Vocabulary 2 Vocabulary 3
B31: LESSON 27 | C31: UNIT 6 DINNER TIME | D31: 42-43 | E31: - Review food, day times and meals - Reading: A day of Alex | F31: Can I have some...., please? - Here you are. - Sorry, I don't have. | G31: - Students can use structure to order the food they want. - For reading part, students can write a short paragraph about their days | H31: 42-43 | I31: =B31 -> LESSON 27 | J31: Grammar 1 & 2
B32: LESSON 28 | C32: UNIT 6 DINNER TIME + SPEAKING PROJECT | D32: 44-45 | E32: - Pronunciation: /ch/ - Listen and watch the story - Speaking Project: Sun 2 Unit 6 Speaking Project | F32: /ch/-/ch/-chicken, kitchen The chicken's lunch is cheese, chips and chocolate! | G32: - Student learn some words start with /oo/ sounds in "Monty's phonics". - With the story, make 3 questions so students answer them after the story - With videos, students can understand the topic | H32: 44-45 | I32: =B32 -> LESSON 28 | J32: Reading 1 & 2 | L32: x
B33: LESSON 29 | C33: UNIT 6 DINNER TIME | D33: 46-47 | E33: - Marie's science: Food + Animals, meat, plants, trees - Trevor's value: Eat good food | F33: - Eggs are from animals. - Carrots are from plants | G33: - Students understand different types of food. - Students understand the value of the lesson. - Students finish the project and talk about it. | H33: 46-47 | I33: =B33 -> LESSON 29 | J33: Vocabulary 1 Grammar 3
B34: LESSON 30 | C34: UNIT 6 DINNER TIME | D34: REVIEW & TEST | E34: - Review Unit 6 (vocabulary and structures) - Unit 6 paper test - Extra book: Story Fun 2 - Uncle Fred and me (Teachers ask students to open Handbook lesson 30) | F34: - What's this? It's ... - What are these? They're .... - I have breakfast in the morning. Can I have some...., please? - Here you are. - Sorry, I don't have. | G34: - Students review all vocabulary and structures | H34: No homework | I34: =B34 -> LESSON 30 | J34: Game 1 and 2
B35: LESSON 31 | C35: REVIEW | D35: 4-17 | E35: Review all vocabularies of Unit 1 and 2 | F35: - Who is this ? - Hello! I'm …. - This is ….. - What letter is it? + It's letter….. - What color is it? + It's …… - Can you spell "PURPLE" ? - What is it ? It's a green cupboard. - How many …. are there? There is/are….. | G35: - Students review the lesson contents of Unit 1 & 2 | H35: No homework | I35: =B35 -> LESSON 31 | J35: Unit 1-2 Game 1 & 2
B36: LESSON 32 | C36: REVIEW | D36: 18-31 | E36: Review all vocabularies of Unit 3 and 4 | F36: - This is a robot. - These are dolls. - Whose is this? It's ….'s. - Whose are these? They are …'s. - Are those blue socks yours? + It's mine/yours. + It's not mine/yours. - Which bag is yours? + The red one's mine. | G36: - Students review the lesson contents of Unit 3 & 4 | H36: No homework | I36: =B36 -> LESSON 32 | J36: Unit 3-4 Game 1 & 2
B37: LESSON 33 | C37: REVIEW | D37: 34-47 | E37: Review all vocabularies of Unit 5 and 6 | F37: - She is Lenny's mother. - He is Lenny's father. - What's he/she doing? He/She is getting/flying/... - What's this? It's ... - What are these? They're .... - I have breakfast in the morning. Can I have some...., please? - Here you are. - Sorry, I don't have. | G37: - Students review the lesson contents of Unit 5 & 6 | H37: No homework | I37: =B37 -> LESSON 33 | J37: Unit 5-6 Game 1 & 2
B38: LESSON 34 | C38: MID-TERM | D38: TEST | E38: MIDTERM TEST - LISTENING, READING, WRITING (For Listening, each part will be listened in 2 times) - Teachers instruct students what to do in each part of the paper test - Teachers prepare worksheets for students to do in class if they finish early - Teachers also can do speaking test for students while they're doing the worksheets | H38: No homework | I38: =B38 -> LESSON 34
B39: LESSON 35 | C39: MID-TERM | D39: TEST | E39: MIDTERM TEST - SPEAKING (See the speaking instruction in Test Answer Key) - Teachers prepare worksheets for students to do in class - Teachers instruct students what to do in each part of the speaking test - Teachers complete the speaking test for all students | H39: No homework | I39: =B39 -> LESSON 35
B40: LESSON 36 | C40: YLE STARTERS | D40: Link | E40: EXTRA BOOK: FUN FOR STARTERS (Unit 31-35) - Students practice Movers Cambridge exam - Teachers ask students to open Handbook, lesson 36 | H40: No homework | I40: No homework
...

Sheet lesson report
B4: Grade | C4: SUN 2
B5: LESSONS | C5: LESSON 1
B6: UNITS | C6: =vlookup($C$5,Syllabus!B:I,2,0) -> UNIT 1 HELLO AGAIN!
B7: Student's book & Activity's book pages | C7: =vlookup($C$5,Syllabus!B:I,3,0) -> 4
B8: Vocabulary Từ vựng | C8: =vlookup($C$5,Syllabus!B:I,4,0) -> - Star's family members: Mr. Star, Mrs. Star, Suzy, Simon, Stella, Maskman, Monty, Grandma Star, Grandpa Star
B9: Grammar Ngữ pháp | C9: =vlookup($C$5,Syllabus!B:I,5,0) -> - Who is this ? - Hello! I'm …. - This is …..
C10: =vlookup($C$5,Syllabus!B:I,6,0) -> Introduce students name and remember the Star's family members
B11: Bài tập về nhà (Handbook) | C11: =vlookup($C$5,Syllabus!B:I,8,0) -> LESSON 1
B12: E-learning

Sheet đánh tay
B4: Grade | C4: SUN 2
B5: LESSONS | C5: LESSON 9
B6: UNITS | C6: UNIT 1 HELLO AGAIN!
B7: Student's book & Activity's book pages | C7: 4
B8: Vocabulary Từ vựng | C8: - Star's family members: Mr. Star, Mrs. Star, Suzy, Simon, Stella, Maskman, Monty, Grandma Star, Grandpa Star
B9: Grammar Ngữ pháp | C9: - Who is this ? - Hello! I'm …. - This is …..
B10: Bài tập về nhà (Handbook) | C10: Lesson 1
B11: E-learning
