Workbook

Sheet Sun 2
A1: SUN 2 SYLLABUS
A2: DATES | B2: LESSONS | C2: UNITS | D2: Student's book & Activity book PAGES | E2: CONTENTS
E3: Vocabulary | F3: Structures | G3: Lesson target | H3: Weekly Practice | I3: Homework
I4: Home work | J4: E-learning (Assigned by CM)
B5: 1 | C5: UNIT 1 HELLO AGAIN! | D5: 4 | E5: Class rules: 1. Be quiet! 2. Sit nicely. 3. Raise your hand 4. Speak English. 5. Listen to teacher - Star's family members: Mr. Star, Mrs. Star, Suzy, Simon, Stella, Maskman, Monty, Grandma Star, Grandpa Star | F5: - Who is this ? What is your name? - Hello! I'm …. How old are you? - I am... - This is ….. | G5: Introduce students name,age and remember the Star's family members Remember the class rules | H5: Video filming: Students take turns to do the Role-play: (Divide the students into pairs) Topic: Good afternoon. Nice to meet you Sample video: https://www.youtube.com/watch?v=pwj1cQiwKBg&list=PLii5rkhsE0Ld3xCgxG6j5fw7RlG2S5czO&index=64 (Teacher prepares the Questions list (if needed) ) " | I5: Handbook p.1 | J5: Vocabulary 2
B6: 2 | C6: UNIT 1 HELLO AGAIN! | D6: 45813 | E6: - Review class rules and characters - Practice singing the song: What's your name? - Film a singing video - Introducing colors: pink, green, grey, orange, red, brown, white, blue, yellow, black, purple. | F6: What is your name? - Hello! I'm …. How old are you? - I am... - This is ….. - Who's he/she? | G6: Students can remember class rules and characters Introduce the student's age and practice using He and She Students be able to sing the song . | I6: Handbook p.2 Quay video/ghi âm tại nhà: Đọc to từ vựng đã học: Class rules: 1. Be quiet! 2. Sit nicely. 3. Raise your hand 4. Speak English. 5. Listen to teacher | J6: Grammar 1
B7: 3 | C7: UNIT 1 HELLO AGAIN! | D7: 7 | E7: - Aphabet - Colors: pink, green, grey, orange, red, brown, white, blue, yellow, black, purple. | F7: - What letter is it? + It's letter….. - What color is it? + It's …… - Can you spell "PURPLE" ? | G7: - Students review the alphabet and colors - Students can spell their names and vocabulary. | I7: Handbook p.3 | J7: Vocabulary 1 & 3 Grammar 2
B8: 4 | C8: UNIT 1 HELLO AGAIN! | D8: 8-9 | E8: - Pronunciation: long vowel sound "ay" - Preposition: On, in, under - Listen to the story -(45 minutes) Unit 1 Speaking video: Unit 1_Speaking Project_Hello again!.pptx | F8: - /ay/ - snake, play, game - /ay/ - Four snakes are playing games! - The pencil is under the chair. | G8: - Student learn some words start with /ay/ sound in "Monty Phonics". Encourage students to know more words. - With the story, make 3 questions so students will answer them after the story - Students stand in front of the class and read the passage fluently (Teacher records the videos) | I8: Handbook p.4 | J8: Reading 1 & 2 Grammar 3
B9: 5 | C9: UNIT 1 HELLO AGAIN! | D9: REVIEW + UNIT TEST 1 | E9: Review Unit 1 (vocabulary and structures) - Star's family members - Alphabet - Colors - (45 minutes) Unit Test 2 | F9: - Who is this ? - Hello! I'm …. - This is ….. - What letter is it? + It's letter….. - What color is it? + It's …… - Can you spell "PURPLE" ? | G9: - Students review all vocabulary and structures | I9: Handbook p.5 | J9: Game 1 and 2
B10: 6 | C10: UNIT 2 BACK TO SCHOOL | D10: 10-11 | E10: - School things: Board, bookcase, ruler, cupboard, teacher, desk. - Numbers: 11 to 20 | F10: - What is it ? It's a green cupboard. - How many desks are there? There are 11 desks. - What number is it? It's number...... | G10: - Students remember the words - Students can use adjective to answer. - Students can use grammar correctly. | H10: Video filming: Students take turns to do the Role-play: (Divide the students into pairs) Topic: Do you have crayons? Sample video: https://www.youtube.com/watch?v=UFy02dqJCUs&list=PLii5rkhsE0Ld3xCgxG6j5fw7RlG2S5czO&index=103 (Teacher prepares the Questions list (if needed) ) | I10: Handbook p.6 Chép từ vào vở, mỗi từ 2 dòng: board, bookcase, ruler | J10: Vocabulary 2&3
B11: 7 | C11: UNIT 2 BACK TO SCHOOL | D11: 12-13 | E11: - Review school things - Reading: Meera's classroom - Sing a song | F11: - How many …. are there? There is/are….. | G11: - Students review the vocabulary - Students practice the grammar in speaking and exercises. - Students can sing a song together | I11: Handbook p.7 Chép từ vào vở, mỗi từ 2 dòng: cupboard, teacher,desk | J11: Vocabulary 1 Grammar 1
B12: 8 | C12: UNIT 2 BACK TO SCHOOL | D12: 14-15 | E12: '- Pronunciation: Long vowel sound "ee" - Listen to the story - Watching video: The hokey cokey - Practice singing the song: What is In Your Bag? Song with Matt | School Classroom Items | Learn English Kids - YouTube - Film a singing video | F12: - /ee/ - three, teacher, tree Three teachers sleeping in a tree - Review there is/are | G12: - Student learn some words start with /ee/ sound in "Monty's phonics". - With the story, make 3 questions so students answer them after the story - With the videos, students can understand and play the game. | I12: Handbook p.8 Quay video/ghi âm tại nhà: Đọc to từ vựng đã học Board, bookcase, ruler, cupboard, teacher, desk | J12: Grammar 2 Reading 1
B13: 9 | C13: UNIT 2 BACK TO SCHOOL | D13: 16-17 | E13: - Marie's math: Block graphs - Fruit: oranges, bananas, apples, pears, pineapples, lemons - Trevor's value: Be polite -(45 minutes) Unit 2 Speaking video: Unit 2_Speaking Project_Back to school.pptx | F13: - Can you … please? Yes, of course. - Can I come in? Yes, come in. - After you. Thank you - What fruit is it? It is ... / They are ... | G13: - Students can use "there is/are" to talk about the block graph - Understand the value of lesson - Students stand in front of the class and read the passage fluently (Teacher records the videos) | I13: Handbook p.9 Chép từ vào vở, mỗi từ 1 dòng: oranges, bananas, apples, pears, pineapples, lemons | J13: Grammar 3 Reading 2
B14: 10 | C14: UNIT 2 BACK TO SCHOOL | D14: REVIEW + TEST | E14: Review Unit 2 (vocabulary and structures) - School's things - Numbers: 11 to 20 | F14: - What is it ? It's a green cupboard. - How many …. are there? There is/are….. | G14: - Students review all vocabulary and structures | I14: Handbook p.10 | J14: Game 1 and 2
B15: 11 | C15: UNIT 3 PLAY TIME! | D15: 18 | E15: - Toys: kite, watch, lorry, alien, robot, camera, computer game | F15: - What is it? It's a…. - Do you like….? Yes, I do./ No, I don't. | G15: Students understand the topic and remember the words | H15: Video filming: Students take turns to do the Role-play: (Divide the students into pairs) Topic: I like soccer. Let's play soccer Sample video: https://www.youtube.com/watch?v=xYGlhOR86mM&list=PLii5rkhsE0Ld3xCgxG6j5fw7RlG2S5czO&index=102 (Teacher prepares the Questions list (if needed) )" | I15: Handbook p.11 Chép từ vào vở, mỗi từ 2 dòng: kite,watch,lorry | J15: Vocabulary 3
B16: 12 | C16: UNIT 3 PLAY TIME! | D16: 19 | E16: - Review Toys - Review numbers: 11 to 20 | F16: - This is a robot. - These are dolls. | G16: Students review the words and use grammar correctly. | I16: Handbook p.12 Chép từ vào vở, mỗi từ 2 dòng: alien,robot, camera, computer game | J16: Vocabulary 1 Grammar 1
B17: 13 | C17: UNIT 3 PLAY TIME! | D17: 18 - 20 | E17: '- Review Toys: kite, watch, lorry, alien, robot, camera, computer game - Sing a song: I Have A Toy | To The Tune of "I Have A Pet" by Super Simple Songs | Noodle & Pals - YouTube | F17: - Whose is this? It's ….'s. - Whose are these? They are …'s. | G17: - Student can use grammar correctly. - Students can sing a song together | I17: Handbook p.13 | J17: Vocabulary 2 Grammar 2
B18: 14 | C18: UNIT 3 PLAY TIME! | D18: 22-23 | E18: ''- Pronunciation: Long vowel sound "ai" - Listen to the story -(45 minutes) Unit 3 Speaking video: Unit 3_Speaking Project_Play time.pptx | F18: /ai/ - fly, five, kite I'm flying my five white kites. | G18: - Student learn some words start with /ai/ sound in "Monty's phonics". - With the story, make 3 questions so students answer them after the story - Students stand in front of the class and read the passage fluently (Teacher records the videos) | I18: Handbook p.14 Quay video/ghi âm tại nhà: Đọc to các từ vựng đã học: kite, watch, lorry, alien, robot, camera, computer game | J18: Grammar 3 Reading 1 & 2
B19: 15 | C19: UNIT 3 PLAY TIME! | D19: REVIEW + UNIT TEST 3 | E19: Review Unit 3 (vocabulary and structures) - Toys - Numbers: 11 to 20 - Unit Test 3 | F19: - This is a robot. - These are dolls. - Whose is this? It's ….'s. - Whose are these? They are …'s. | G19: - Students review all vocabulary and structures | I19: Handbook p.15 | J19: Game 1 and 2
B20: 16 | C20: UNIT 4 AT HOME | D20: 24-25 | E20: - Things in a house: mirror, mat, sofa, phone, lamp, clock. - Review rooms in a house. | F20: - What is it? It's a... - There is…..in the living room. | G20: Students remember the words and use them with structure correctly. | H20: Video filming: Students take turns to do the Role-play: (Divide the students into pairs) Topic: What's this? Sample video: https://www.youtube.com/watch?v=j-XXk3dVeag&list=PLii5rkhsE0Ld3xCgxG6j5fw7RlG2S5czO&index=63 (Teacher prepares the Questions list (if needed) )" | I20: Handbook p.16 Chép từ vào vở, mỗi từ 2 dòng: mirror, mat, sofa | J20: Vocabulary 2
B21: 17 | C21: UNIT 4 AT HOME | D21: 26-27 | E21: - Review things in a house - Sing a song - Possessive pronouns: Mine, yours, his, hers | F21: - Are those blue socks yours? + It's mine/yours. + It's not mine/yours. - Which bag is yours? + The red one's mine. | G21: - Student can use grammar correctly - Students can sing a song together | I21: Handbook p.17 Chép từ vào vở, mỗi từ 2 dòng: phone, lamp, clock | J21: Vocabulary 1 Grammar 3
B22: 18 | C22: UNIT 4 AT HOME | D22: 28-29 | E22: - Pronunciation: Long vowel sound: "oa/oe/ow" - Listen to the story | F22: /oe/ - phone /ow/ - yellow /oa/ - boat A phone in a yellow boat! - Review yours/mine. | G22: - Student learn some words start with /oe/, /ow/ and /oa/ sounds in "Monty's phonics". - With the story, make 3 questions so students answer them after the story - With videos, students can understand how to decorate a box | I22: Handbook p.18 | J22: Vocabulary 3 Grammar 2 & 3
B23: 19 | C23: UNIT 4 AT HOME | D23: 30-31 | E23: - Marie's art: Origami - Trevor values: Re-use and recycle - New words: bottles, flowerpot, keyboard, plastic bags -(45 minutes) Unit 4 Speaking video: Unit 4_Speaking Project_At home.pptx | F23: - What's this? It's a….. - What's it made from? It's made from …. | G23: - Students understand the topic (orgiami) - Understnd the value of re-use and recycle. - Students stand in front of the class and read the passage fluently (Teacher records the videos) | I23: Handbook p.19 Quay video/ghi âm tại nhà: Đọc to các từ vựng đã học: mirror, mat, sofa, phone, lamp, clock. | J23: Grammar 1 Reading 1 & 2
B24: 20 | C24: UNIT 4 AT HOME | D24: REVIEW + UNIT TEST 4 | E24: Review Unit 4 (vocabulary and structures) - Things in a house - Rooms | F24: - Are those blue socks yours? + It's mine/yours. + It's not mine/yours. - Which bag is yours? + The red one's mine. | G24: - Students review all vocabulary and structures | H24: Creative Lesson: Create your own Family Tree: Draw and write about your family on the Tree (Blank Template) then share about it: Small-Family-Tree-Template.pdf | I24: Handbook p.20 | J24: Game 1 and 2
B25: 21 | C25: UNIT 5 MEET MY FAMILY | D25: 34 | E25: - Family members: mum, dad, grandma, baby, cousin | F25: - Who is this? He/She is.... | G25: Students understand the topic and remember the words | I25: Handbook p.21 | J25: Vocabulary 3
B26: 22 | C26: UNIT 5 MEET MY FAMILY | D26: 35 | E26: - Review family members - Learn about family tree | F26: - She is Lenny's mother. - He is Lenny's father. | G26: Students review the vocabular and understand the family tree | I26: Handbook p.22 Chép từ vào vở, mỗi từ 01 dòng: mum, dad, grandma, baby, cousin | J26: Vocabulary 1 Grammar 2
B27: 23 | C27: UNIT 5 MEET MY FAMILY | D27: 36-37 | E27: - Verb: getting, throwing, catching, flying, talking, jumping, sitting, hitting, cleaning, running, kicking, sleeping - Sing a song | F27: - What's he/she doing? He/She is getting/flying/... | G27: - Students remember the verb. - Students can use grammar to talk about people in the picture correctly. - Students can sing a song together. | I27: Handbook p.23 | J27: Vocabulary 2 Grammar 3
B28: 24 | C28: UNIT 5 MEET MY FAMILY | D28: 38-39 | E28: - Pronunciation: long vowel sound "oo" - Watch a story -(45 minutes) Unit 5 Speaking video: https://docUnit 5_Speaking Project_Meet my family.pptx | F28: - Blue - Sue - Ruler - Sue's got a big blue ruler. | G28: - Student learn some words start with /oo/ sounds in "Monty's phonics". - With the story, make 3 questions so students answer them after the story - Students stand in front of the class and read the passage fluently (Teacher records the videos) | I28: Handbook p.24 Quay video/ghi âm tại nhà: Đọc to các từ vựng đã học: mum, dad, grandma, baby, cousin. | J28: Grammar 1 Reading 1 & 2
B29: 25 | C29: UNIT 5 MEET MY FAMILY | D29: REVIEW + UNIT TEST 5 | E29: Review Unit 5 (vocabulary and structures) - Family members - (45 minutes) Unit Test 5 | F29: - She is Lenny's mother. - He is Lenny's father. - What's he/she doing? He/She is getting/flying/... | G29: - Students review all vocabulary and structures | I29: Handbook p.25 | J29: Game 1 and 2
B30: 26 | C30: UNIT 6 DINNER TIME | D30: 40-41 | E30: - Food: Bread, water, milk, juice, chicken, eggs, chips, rice - Day times: Morning, lunchtime, afternoon, evening - Meals: Breakfast, lunch, dinner - Sing a song activity | F30: - What's this food? It's ... - What are these? They're .... - I have breakfast in the morning. | G30: - Students remember the words - Students know how to say the meal in different time of a day (breakfast for morning time, dinner for evening time,...) - Students can sing a song together. | H30: Video filming: Students take turns to do the Role-play: (Divide the students into pairs) Topic: May I take your order? Sample video: https://www.youtube.com/watch?v=49QFHWIky-k&list=PLii5rkhsE0Ld3xCgxG6j5fw7RlG2S5czO&index=69 (Teacher prepares the Questions list (if needed) )" | I30: Handbook p.26 Chép từ mới vào vở, mỗi từ 02 dòng: bread, milk, water, juice | J30: Vocabulary 2 Vocabulary 3
B31: 27 | C31: UNIT 6 DINNER TIME | D31: 42-43 | E31: - Review food, day times and meals - Reading: A day of Alex | F31: Can I have some...., please? - Here you are. - Sorry, I don't have. | G31: - Students can use structure to order the food they want. - For reading part, students can write a short paragraph about their days | I31: Handbook p.27 Chép từ mới vào vở, mỗi từ 02 dòng: chicken, eggs, chips, rice | J31: Grammar 1 & 2
B32: 28 | C32: UNIT 6 DINNER TIME | D32: 44-45 | E32: - Pronunciation: /ch/ - Watch the story | F32: /ch/-/ch/-chicken, kitchen The chickens are cooking in the kitchen. | G32: - Student learn some words start with /oo/ sounds in "Monty's phonics". - With the story, make 3 questions so students answer them after the story - With videos, students can understand the topic | H32: Draw your favorite meals and describe (CM prints the template) Draw a meal for elementary students Worksheet.jpg | I32: Handbook p.28 | J32: Reading 1 & 2
B33: 29 | C33: UNIT 6 DINNER TIME | D33: 46-47 | E33: - Marie's science: Food + Animals, meat, plants, trees - Trevor's value: Eat good food -(40 minutes) Unit 6 Speaking video: Unit 6_Speaking Project_Dinner time.pptx | F33: - Eggs are from animals. - Carrots are from plants | G33: - Students understand different types of food. - Students understand the value of the lesson. - Students stand in front of the class and read the passage fluently (Teacher records the videos) | I33: Handbook p.29 Quay video/ghi âm tại nhà: Đọc to các từ vựng đã học: Bread, water, milk, juice, chicken, eggs, chips, rice | J33: Vocabulary 1 Grammar 3
B34: 30 | C34: UNIT 6 DINNER TIME | D34: REVIEW + UNIT TEST 6 | E34: Review Unit 6 (vocabulary and structures) - Food - Day times and Meals | F34: - What's this? It's ... - What are these? They're .... - I have breakfast in the morning. Can I have some...., please? - Here you are. - Sorry, I don't have. | G34: - Students review all vocabulary and structures | I34: Handbook p.30 | J34: Game 1 and 2
B35: 31 | C35: REVIEW | D35: 4-17 | E35: Review all vocabularies of Unit 1 and 2 | F35: - Who is this ? - Hello! I'm …. - This is ….. - What letter is it? + It's letter….. - What color is it? + It's …… - Can you spell "PURPLE" ? - What is it ? It's a green cupboard. - How many …. are there? There is/are….. | G35: - Students review the lesson contents of Unit 1 & 2 | J35: Unit 1-2 Game 1 & 2
B36: 32 | C36: REVIEW | D36: 18-31 | E36: Review all vocabularies of Unit 3 and 4 | F36: - This is a robot. - These are dolls. - Whose is this? It's ….'s. - Whose are these? They are …'s. - Are those blue socks yours? + It's mine/yours. + It's not mine/yours. - Which bag is yours? + The red one's mine. | G36: - Students review the lesson contents of Unit 3 & 4 | J36: Unit 3-4 Game 1 & 2
B37: 33 | C37: REVIEW | D37: 34-47 | E37: Review all vocabularies of Unit 5 and 6 | F37: - She is Lenny's mother. - He is Lenny's father. - What's he/she doing? He/She is getting/flying/... - What's this? It's ... - What are these? They're .... - I have breakfast in the morning. Can I have some...., please? - Here you are. - Sorry, I don't have. | G37: - Students review the lesson contents of Unit 5 & 6 | J37: Unit 5-6 Game 1 & 2
B38: 34 | C38: MID-TERM | D38: TEST | E38: MID-TERM TEST - READING, WRITING AND SPEAKING (Speaking test for students whose finish the reading and writing test early. Teachers prepare extra materials for students) | I38: Fun for Starter (21-25)
B39: 35 | C39: MID-TERM | D39: TEST | E39: MID-TERM SPEAKING TEST (Speaking test for students whose aren't finished) | I39: Fun for Starter (26-30)
B40: 36 | C40: YLE MOVERS | E40: CAMBRIDGE A1 MOVERS MOCK TEST Listening + Reading + Writing | F40: (55 minutes) CAMBRIDGE MOVERS MOCK TEST: Link test: A1 Movers (25 minutes) Test correction + Mini reflection | I40: Fun for Starter (31-35)
...

Sheet Lesson Report Sun 2
B4: Grade | C4: SUN 2
B5: LESSONS | C5: 52
B6: UNITS | C6: =vlookup($C$5,'Sun 2'!$B$5:$J$76,2,0) -> UNIT 10 OUR HOBBIES
B7: Student's book & Activity's book pages | C7: =vlookup($C$5,'Sun 2'!$B$5:$J$76,3,0) -> 70-71
B8: Vocabulary | C8: =vlookup($C$5,'Sun 2'!$B$5:$J$76,4,0) -> - Hobbies: painting, table tennis, hockey, badminton, basketball, baseball. - Reading: football and soccer.
B9: Structures | C9: =vlookup($C$5,'Sun 2'!$B$5:$J$76,5,0) -> - What's this? It's..... - My hobby is....
B10: Lesson target | C10: =vlookup($C$5,'Sun 2'!$B$5:$J$76,6,0) -> - Students know the different between sports and hobbies - Students remember the words and use them with structure correctly.
B11: BTVN - sách Handbook | C11: =vlookup($C$5,'Sun 2'!$B$5:$J$76,8,0) -> Handbook p.46
B12: E-learning | C12: Unit 10 Vocabulary 1 + 3

Sheet Sửa
A1: DATES | B1: LESSONS | C1: UNITS | D1: Student's book & Activity book PAGES | E1: CONTENTS | J1: Classroom materials
E2: Vocabulary | F2: Grammar/Structures | G2: Lesson target | H2: Homework
H3: Handbook | I3: E-learning (Assigned by CM)
B5: LESSON 1 | C5: UNIT 1 HELLO AGAIN! | D5: 4 | E5: - Star's family members: Mr. Star, Mrs. Star, Suzy, Simon, Stella, Maskman, Monty, Grandma Star, Grandpa Star | F5: - Who is this ? - Hello! I'm …. - This is ….. | G5: Introduce students name and remember the Star's family members | H5: 1 | I5: Vocabulary 2
B6: LESSON 2 | C6: UNIT 1 HELLO AGAIN! | D6: 45813 | E6: - Review characters | F6: - What's your name? - How old are you? - Who's he/she? | G6: Introduce the student's age and practice using He and She. | H6: 2 | I6: Grammar 1
B7: LESSON 3 | C7: UNIT 1 HELLO AGAIN! | D7: 7 | E7: - Aphabet - Colors: pink, green, grey, orange, red, brown, white, blue, yellow, black, purple. | F7: - What letter is it? + It's letter….. - What color is it? + It's …… - Can you spell "PURPLE" ? | G7: - Students review the alphabet and colors - Students can spell their names and vocabulary. | H7: 3 | I7: Vocabulary 1 & 3 Grammar 2
B8: LESSON 4 | C8: UNIT 1 HELLO AGAIN! | D8: 45908 | E8: - Pronunciation: long vowel sound "ay" - Preposition: On, in, under - Listen to the story -(45 minutes) Unit 1 Speaking video: Unit 1.pptx | F8: - /ay/ - snake, play, game - /ay/ - Four snakes are playing games! - The pencil is under the chair. | G8: - Student learn some words start with /ay/ sound in "Monty Phonics". Encourage students to know more words. - With the story, make 3 questions so students will answer them after the story - Students stand in front of the class and read the passage fluently (Teacher records the videos) | H8: 4 | I8: Reading 1 & 2 Grammar 3
B9: LESSON 5 | C9: UNIT 1 HELLO AGAIN! | D9: Project | F9: - Who is this ? - Hello! I'm …. - This is ….. - What letter is it? + It's letter….. - What color is it? + It's …… - Can you spell "PURPLE" ?
B10: LESSON 6 | C10: UNIT 2 BACK TO SCHOOL | D10: 45971 | E10: - School things: Board, bookcase, ruler, cupboard, teacher, desk. - Numbers: 11 to 20 | F10: - What is it ? It's a green cupboard. - How many desks are there? There are 11 desks. | G10: - Students remember the words - Students can use adjective to answer. - Students can use grammar correctly. | H10: 6 | I10: Vocabulary 2&3
B11: LESSON 7 | C11: UNIT 2 BACK TO SCHOOL | D11: 12-13 | E11: - Review school things - Reading: Meera's classroom - Sing a song | F11: - How many …. are there? There is/are….. | G11: - Students review the vocabulary - Students practice the grammar in speaking and exercises. - Students can sing a song together | H11: 7 | I11: Vocabulary 1 Grammar 1
B12: LESSON 8 | C12: UNIT 2 BACK TO SCHOOL | D12: 14-15 | E12: - Pronunciation: Long vowel sound "ee" - Listen to the story - Watching video: The hokey cokey | F12: - /ee/ - three, teacher, tree Three teachers sleeping in a tree - Review there is/are | G12: - Student learn some words start with /ee/ sound in "Monty's phonics". - With the story, make 3 questions so students answer them after the story - With the videos, students can understand and play the game. | H12: 8 | I12: Grammar 2 Reading 1
B13: LESSON 9 | C13: UNIT 2 BACK TO SCHOOL | D13: 16-17 | E13: - Marie's math: Block graphs - Fruit: oranges, bananas, apples, pears, pineapples, lemons - Trevor's value: Be polite -(45 minutes) Unit 2 Speaking video: Unit 2.pptx | F13: - Can you … please? Yes, of course. - Can you come in? Yes, come in. | G13: - Students can use "there is/are" to talk about the block graph - Understand the value of lesson - Students stand in front of the class and read the passage fluently (Teacher records the videos) | H13: 9 | I13: Grammar 3 Reading 2
B14: LESSON 10 | C14: UNIT 2 BACK TO SCHOOL | D14: Project | F14: - What is it ? It's a green cupboard. - How many …. are there? There is/are…..
B15: LESSON 11 | C15: LESSON 31 | D15: REVIEW + TEST U1+U2 | E15: 4-17 | F15: Review all vocabularies of Unit 1 and 2 | G15: - Who is this ? - Hello! I'm …. - This is ….. - What letter is it? + It's letter….. - What color is it? + It's …… - Can you spell "PURPLE" ? - What is it ? It's a green cupboard. - How many …. are there? There is/are….. | H15: - Students review the lesson contents of Unit 1 & 2 | I15: Homebooklet Unit 1&2 | J15: Unit 1-2 Game 1 & 2
B16: LESSON 12 | C16: UNIT 3 PLAY TIME! | D16: 18 | E16: - Toys: kite, watch, lorry, alien, robot, camera, computer game | F16: - What is it? It's a…. - Do you like….? Yes, I do./ No, I don't. | G16: Students understand the topic and remember the words | H16: 11 | I16: Vocabulary 3
B17: LESSON 13 | C17: UNIT 3 PLAY TIME! | D17: 19 | E17: - Review Toys - Review numbers: 11 to 20 | F17: - This is a robot. - These are dolls. | G17: Students review the words and use grammar correctly. | H17: 12 | I17: Vocabulary 1 Grammar 1
B18: LESSON 14 | C18: UNIT 3 PLAY TIME! | D18: 20 | E18: - Review Toys - Sing a song | F18: - Whose is this? It's ….'s. - Whose are these? They are …'s. | G18: - Student can use grammar correctly. - Students can sing a song together | H18: 13 | I18: Vocabulary 2 Grammar 2
B19: LESSON 15 | C19: UNIT 3 PLAY TIME! | D19: 22-23 | E19: '- Pronunciation: Long vowel sound "ai" - Listen to the story -(45 minutes) Unit 3 Speaking video: Unit 3.pptx | F19: /ai/ - fly, five, kite I'm flying my five white kites. | G19: - Student learn some words start with /ai/ sound in "Monty's phonics". - With the story, make 3 questions so students answer them after the story - Students stand in front of the class and read the passage fluently (Teacher records the videos) | H19: 14 | I19: Grammar 3 Reading 1 & 2
B20: LESSON 16 | C20: UNIT 3 PLAY TIME! | D20: Project | F20: - This is a robot. - These are dolls. - Whose is this? It's ….'s. - Whose are these? They are …'s.
B21: LESSON 17 | C21: UNIT 4 AT HOME | D21: 24-25 | E21: - Things in a house: mirror, mat, sofa, phone, lamp, clock. - Review rooms in a house. | F21: - What is it? It's a... - There is…..in the living room. | G21: Students remember the words and use them with structure correctly. | H21: 16 | I21: Vocabulary 2
B22: LESSON 18 | C22: UNIT 4 AT HOME | D22: 26-27 | E22: - Review things in a house - Sing a song - Possessive pronouns: Mine, yours, his, hers | F22: - Are those blue socks yours? + It's mine/yours. + It's not mine/yours. - Which bag is yours? + The red one's mine. | G22: - Student can use grammar correctly - Students can sing a song together | H22: 17 | I22: Vocabulary 1 Grammar 3
B23: LESSON 19 | C23: UNIT 4 AT HOME | D23: 28-29 | E23: - Pronunciation: Long vowel sound: "oa/oe/ow" - Listen to the story | F23: /oe/ - phone /ow/ - yellow /oa/ - boat A phone in a yellow boat! - Review yours/mine. | G23: - Student learn some words start with /oe/, /ow/ and /oa/ sounds in "Monty's phonics". - With the story, make 3 questions so students answer them after the story - With videos, students can understand how to decorate a box | H23: 18 | I23: Vocabulary 3 Grammar 2 & 3
B24: LESSON 20 | C24: UNIT 4 AT HOME | D24: 30-31 | E24: - Marie's art: Origami - Trevor values: Re-use and recycle - New words: bottles, flowerpot, keyboard, plastic bags -(45 minutes) Unit 4 Speaking video: Unit 4.pptx | F24: - What's this? It's a….. - What's it made from? It's made from …. | G24: - Students understand the topic (orgiami) - Understnd the value of re-use and recycle. - Students stand in front of the class and read the passage fluently (Teacher records the videos) | H24: 19 | I24: Grammar 1 Reading 1 & 2
B25: LESSON 21 | C25: UNIT 4 AT HOME | D25: Project | F25: - Are those blue socks yours? + It's mine/yours. + It's not mine/yours. - Which bag is yours? + The red one's mine.
B26: LESSON 22 | C26: REVIEW + Test U3+U4 | D26: 18-31 | E26: Review all vocabularies of Unit 3 and 4 | F26: - This is a robot. - These are dolls. - Whose is this? It's ….'s. - Whose are these? They are …'s. - Are those blue socks yours? + It's mine/yours. + It's not mine/yours. - Which bag is yours? + The red one's mine. | G26: - Students review the lesson contents of Unit 3 & 4 | H26: Homebooklet Unit 3&4 | I26: Unit 3-4 Game 1 & 2
B27: LESSON 23 | C27: UNIT 5 MEET MY FAMILY | D27: 34 | E27: - Family members: mum, dad, baby, grandma, baby, cousin | F27: - Who is this? He/She is.... | G27: Students understand the topic and remember the words | H27: 21 | I27: Vocabulary 3
B28: LESSON 24 | C28: UNIT 5 MEET MY FAMILY | D28: 35 | E28: - Review family members - Learn about family tree | F28: - She is Lenny's mother. - He is Lenny's father. | G28: Students review the vocabular and understand the family tree | H28: 22 | I28: Vocabulary 1 Grammar 2
B29: LESSON 25 | C29: UNIT 5 MEET MY FAMILY | D29: 36-37 | E29: - Verb: getting, throwing, catching, flying, talking, jumping, sitting, hitting, cleaning, running, kicking, sleeping - Sing a song | F29: - What's he/she doing? He/She is getting/flying/... | G29: - Students remember the verb. - Students can use grammar to talk about people in the picture correctly. - Students can sing a song together. | H29: 23 | I29: Vocabulary 2 Grammar 3
B30: LESSON 26 | C30: UNIT 5 MEET MY FAMILY | D30: 38-39 | E30: - Pronunciation: long vowel sound "oo" - Watch a story -(45 minutes) Unit 5 Speaking video: Unit 5.pptx | F30: - Blue - Sue - Ruler - Sue's got a big blue ruler. | G30: - Student learn some words start with /oo/ sounds in "Monty's phonics". - With the story, make 3 questions so students answer them after the story - Students stand in front of the class and read the passage fluently (Teacher records the videos) | H30: 24 | I30: Grammar 1 Reading 1 & 2
B31: LESSON 27 | C31: UNIT 5 MEET MY FAMILY | D31: Project | F31: - She is Lenny's mother. - He is Lenny's father. - What's he/she doing? He/She is getting/flying/...
B32: LESSON 28 | C32: UNIT 6 DINNER TIME | D32: 40-41 | E32: - Food: Bread, water, milk, juice, chicken, eggs, chips, rice - Day times: Morning, lunchtime, afternoon, evening - Meals: Breakfast, lunch, dinner - Sing a song activity | F32: - What's this? It's ... - What are these? They're .... - I have breakfast in the morning. | G32: - Students remember the words - Students know how to say the meal in different time of a day (breakfast for morning time, dinner for evening time,...) - Students can sing a song together. | H32: 26 | I32: Vocabulary 2 Vocabulary 3
B33: LESSON 29 | C33: UNIT 6 DINNER TIME | D33: 42-43 | E33: - Review food, day times and meals - Reading: A day of Alex | F33: Can I have some...., please? - Here you are. - Sorry, I don't have. | G33: - Students can use structure to order the food they want. - For reading part, students can write a short paragraph about their days | H33: 27 | I33: Grammar 1 & 2
B34: LESSON 30 | C34: UNIT 6 DINNER TIME | D34: 44-45 | E34: - Pronunciation: /ch/ - Watch the story | F34: /ch/-/ch/-chicken, kitchen The chickens are cooking in the kitchen. | G34: - Student learn some words start with /oo/ sounds in "Monty's phonics". - With the story, make 3 questions so students answer them after the story - With videos, students can understand the topic | H34: 28 | I34: Reading 1 & 2
B35: LESSON 31 | C35: UNIT 6 DINNER TIME | D35: 46-47 | E35: - Marie's science: Food + Animals, meat, plants, trees - Trevor's value: Eat good food -(40 minutes) Unit 6 Speaking video: Unit 6.pptx | F35: - Eggs are from animals. - Carrots are from plants | G35: - Students understand different types of food. - Students understand the value of the lesson. - Students stand in front of the class and read the passage fluently (Teacher records the videos) | H35: 29 | I35: Vocabulary 1 Grammar 3
B36: LESSON 32 | C36: UNIT 6 DINNER TIME | D36: Project | F36: - What's this? It's ... - What are these? They're .... - I have breakfast in the morning. Can I have some...., please? - Here you are. - Sorry, I don't have.
B37: LESSON 33 | C37: REVIEW + Test U5+U6 | D37: 34-47 | E37: Review all vocabularies of Unit 5 and 6 | F37: - She is Lenny's mother. - He is Lenny's father. - What's he/she doing? He/She is getting/flying/... - What's this? It's ... - What are these? They're .... - I have breakfast in the morning. Can I have some...., please? - Here you are. - Sorry, I don't have. | G37: - Students review the lesson contents of Unit 5 & 6 | H37: Homebooklet Unit 5&6 | I37: Unit 5-6 Game 1 & 2
B38: LESSON 34 | C38: REVIEW | D38: 4-17 | E38: Review all vocabularies of Unit 1 and 2 | F38: - Who is this ? - Hello! I'm …. - This is ….. - What letter is it? + It's letter….. - What color is it? + It's …… - Can you spell "PURPLE" ? - What is it ? It's a green cupboard. - How many …. are there? There is/are….. | G38: - Students review the lesson contents of Unit 1 & 2 | H38: Homebooklet Unit 1&2 | I38: Unit 1-2 Game 1 & 2
B39: LESSON 35 | C39: REVIEW | D39: 18-31 | E39: Review all vocabularies of Unit 3 and 4 | F39: - This is a robot. - These are dolls. - Whose is this? It's ….'s. - Whose are these? They are …'s. - Are those blue socks yours? + It's mine/yours. + It's not mine/yours. - Which bag is yours? + The red one's mine. | G39: - Students review the lesson contents of Unit 3 & 4 | H39: Homebooklet Unit 3&4 | I39: Unit 3-4 Game 1 & 2
B40: LESSON 36 | C40: MID-TERM | D40: TEST | E40: MID-TERM TEST - READING, WRITING AND SPEAKING (Speaking test for students whose finish the reading and writing test early. Teachers prepare extra materials for students) | H40: Fun for Starter (21-25) | J40: Link test
B42: LESSON 37 | C42: UNIT 7 AT THE FARM | D42: 48 | E42: - Farm animals: sheep, duck, spider, frog, lizard, goat, cow | F42: What animal is it? It's a.... | G42: - Students understand the topic and remember the words - Students understand the different between farm animals with other animals. | H42: 31 | I42: Vocabulary 2
...
