Workbook

Sheet Sun 1
A1: SUN 1 SYLLABUS
A2: DATES | B2: LESSONS | C2: UNIT | D2: Student's book & Activity's book PAGES | E2: CONTENTS
E3: Vocabulary | F3: Structures | G3: Lesson target | H3: Weekly Practice | I3: Homework
I4: Handbook | J4: E-learning (Assigned by CM)
A5: Stage 1: Seed 1
B6: LESSON 1 | C6: UNIT 1 HELLO! | D6: 4 | E6: Class rules: 1. Be quiet! 2. Sit nicely. 3. Raise your hand 4. Speak English. 4. Listen to teacher - Star's family members: Mr. Star, Mrs. Star, Suzy, Simon, Stella, Maskman, Monty | F6: Greetings: Hello, I'm ..... Goodbye What's your name? My name is..../I'm...... How old are you? I'm (seven) years old. What color is the ......? It's ....... | G6: Students remember class rules Students know how to greet each other Students know how to ask and answer questions about name, age and color | H6: Video filming: Students take turns to do the Role-play: (Divide the students into pairs) Topic: How old are you Sample video: How old are you? - [Age] - Renewal - Easy Dialogue - Role Play - YouTube (Teacher prepares the Questions list (if needed) ) | I6: 1 | J6: Vocabulary 1
B7: LESSON 2 | C7: UNIT 1 HELLO! | D7: 5-6 | E7: - Review Star's family members: Mr. Star, Mrs. Star, Suzy, Simon, Stella, Maskman, Monty - Numbers - Chant : 1-10 - New character: Meera | F7: Review: Greetings: Hello, I'm ..... Goodbye What's your name? My name is..../I'm...... How old are you? I'm….. (years old) This is ..... | G7: Students remember Vocabularies and Structure from Lesson 1 Students can ask and answer question: "How old are you? I'm .... (years old)" Students can answer characters and family members using "This is....." | I7: 2 | J7: Vocabulary 3 Grammar 1
B8: LESSON 3 | C8: UNIT 1 HELLO! | D8: 7 | E8: - Colors: Pink, orange, yellow, red, blue, green, purple - Sing the song (CD1-10) - Speaking activity: Mixing colors and explain: "What color is it"? | F8: What color is it? It's …. | G8: Students can remember vocabularies about Colors Students can ask and answer "What color is it? It's ..." Students can sing the song, do the activity and speak | I8: 3 | J8: Vocabulary 2 Grammar 2
B9: LESSON 4 | C9: UNIT 1 HELLO! Review + Speaking Project | D9: 8-9 | E9: - Pronunciation: /s/ - Listen to the story (CD1 - 17) -(45 minutes) Unit 1: Speaking Project: Sun 1_Unit 1_Speaking Project 1.pptx | F9: /s/-/s/-six /s/-/s/-star /s/-/s/-six stars | G9: - Student learn some words start with /s/ sound in "Say it with Monty". Encourage students to know more words. - With the story, make 3 questions so students will answer them after the story - Students stand in front of the class and do the Speaking Project (Teacher records the videos) | I9: 4 | J9: Grammar 3
B10: LESSON 5 | C10: UNIT 1 HELLO! | D10: RREVIEW+ UNIT TEST | E10: Review Unit 1 (vocabulary and structures) - Star's family members - Numbers 1-10 - Colors - (45 minutes) Unit Test 1 | F10: Hello! I'm …. This is ….. How old are you? I'm….. What color is it? It's …. | G10: - Students review all vocabulary and structures | J10: Game 1 and 2
B11: LESSON 6 | C11: UNIT 2 MY SCHOOL | D11: 10-11 | E11: - School things: Table,Book,Chair,Eraser, Pen, Pencil - Chant (CD1-22): Say the chant - Listen and correct (CD1-23) | F11: What is it ? It's a… Four purple chairs, six orange chairs How are you? I'm fine, thank you. | G11: Remember school things Start using adjective with noun | H11: Video filming: Students take turns to do the Role-play: (Divide the students into pairs) Topic: Do you have Crayons? Sample video: Do you have crayons? - [Have] - Renewal - Easy Dialogue - Role Play - YouTube (Teacher prepares the Questions list (if needed) ) | I11: 5 | J11: Vocabulary 1
B12: LESSON 7 | C12: UNIT 2 MY SCHOOL | D12: 12-13 | E12: - Review School things Vocabularies: Table,Book,Chair,Eraser, Pen, Pencil (Lesson 6) - New Characters: Lenny and Alex - Craft project and speaking: Make the puppets (page 13) | F12: Who's that? He's (Alex). She's (Meera) Who is she/he? She/He is …. How old is he/she? He/she is (six) | G12: Understand the differents between He and She Students know how to describe objects that related to the project | I12: 6 | J12: Vocabulary 2 Grammar 2
B13: LESSON 8 | C13: UNIT 2 MY SCHOOL | D13: 14-15 | E13: - Pronunciation (initial letter sounds) : /p/ and /b/ - The story - Watching video: Simon says | F13: /p/-/p/-pen /b/-/b/-bag A pink pen and a blue bag | G13: - Student learn some words start with /p/ and /b/ sound in "Say it with Monty". - With the story, make 3 question so student answer them after the story - With the videos, students can understand and play the game. | I13: 7 | J13: Vocabulary 3 Grammar 1
B14: LESSON 9 | C14: UNIT 2 MY SCHOOL | D14: 16-17 | E14: Maths: Marie's maths: Adding: Look and say the number - Trevor values: (Story) Make friends -(45 minutes) Unit 2 Speaking video: Sun 1_Unit 2_Speaking Project.pptx | F14: 1 pen and 2 pens is 3 pens | G14: - Students can use adding math to count things in English. - Understand the value of making friends - Students stand in front of the class and read the passage fluently ( Teacher records the videos) | I14: 8 | J14: Grammar 3
B15: LESSON 10 | C15: UNIT 2 MY SCHOOL | D15: REVIEW + UNIT TEST | E15: Review Unit 2 (vocabulary and structures) - School things - New characters: Lenny and Alex - (45 minutes) Unit Test 2 | F15: What is it ? It's a… Four purple chairs, six orange chairs Who's that? He's (Alex). She's (Meera) Who is she/he? She/He is …. How old is he/she? He/she is (six)" | G15: - Students review all vocabulary and structures - Students do the Unit Test | J15: Game 1 and 2
B16: LESSON 11 | C16: UNIT 3 FAVORITE TOYS | D16: 18 | E16: - Toys: Ball, bike, car, computer, doll, train | F16: My favorite toys is a red car | G16: Students understand the topic and remember the words | H16: Video filming: Students take turns to do the Role-play: (Divide the students into pairs) Topic: What color is it? Sample video:What color is it? - [Color] - Renewal - Easy Dialogue - Role Play - YouTube (Teacher prepares the Questions list (if needed) ) | I16: 9 | J16: Vocabulary 1
B17: LESSON 12 | C17: UNIT 3 FAVORITE TOYS | D17: 19 | E17: - Review lesson 11 - New words: black, brown, white, grey | F17: It's a green ball. It's a black car. | G17: Students remember new colors and use them with toy's words. | I17: 10 | J17: Vocabulary 2 Grammar 1
B18: LESSON 13 | C18: UNIT 3 FAVORITE TOYS | D18: 20-21-22 | E18: - Prepositions: In, on, under, next to - Sing a song | F18: - Is a ball under the chair? Yes, it is No, it isn't - Where is it? It's on the chair. | G18: - Student can remember prepositions and use them correctly. - Students can sing a song together | I18: 11 | J18: Vocabulary 3 Grammar 2
B19: LESSON 14 | C19: UNIT 3 FAVORITE TOYS | D19: 22-23 | E19: '- Pronunciation: /t/ and /d/ - Watch the story - (45 minutes) Unit 3 Speaking video: UNIT 3 PRESENTATION TOYS AND COLORS.pptx | F19: /t/-/t/-train /d/-/d/-doll Ten dolls on a train. | G19: - Student learn some words start with /t/ sound in "Say it with Monty". - With the story, make 3 question so students answer them after the story - Students stand in front of the class and read the passage fluently ( Teacher records the videos) | I19: 12 | J19: Grammar 3
B20: LESSON 15 | C20: UNIT 3 FAVORITE TOYS | D20: REVIEW + TEST | E20: Review Unit 3 (vocabulary and structures) - Toys - New colors - Prepositions | F20: My favorite toys is a red car It's a green ball. It's a black car. - Is a ball under the chair? Yes, it is No, it isn't - Where is it? It's on the chair. | G20: - Students review all vocabulary and structures | J20: Game 1 and 2
B21: LESSON 16 | C21: UNIT 4 MY FAMILY | D21: 24-25 | E21: - Family: Mother, Father, Brother, Sister, grandma, grandpa | F21: This is my….. He/She is my | G21: Students remember the words and use them with structure correctly. | H21: Video filming: Drawing and presenting: Draw a family tree and introduce about Family members Template: Family Tree Template.pdf | I21: 13 | J21: Vocabulary 1
B22: LESSON 17 | C22: UNIT 4 MY FAMILY | D22: 26-27 | E22: - Review lesson 16 - New words: Old-young, ugly-beautiful, happy-sad - Sing a song | F22: She is happy He is sad | G22: - Student can remember adjectives and use them correctly. - Students can sing a song together | I22: 14 | J22: Vocabulary 2 Grammar 1
B23: LESSON 18 | C23: UNIT 4 MY FAMILY | D23: 28-29 | E23: - Pronunciation: /a/ - Watch the story (read along the script) - Student role play Story: https://youtu.be/s9RuBAvENhI?si=Pcbcih78PUSKIv2X&t=127 | F23: /a/-/a/-sad Sad cat | G23: - Student learn some words start with /a/ sound in "Say it with Monty". - With the story, make 3 question so students answer them after the story - Student do a role play (Teacher records and give some comments) | I23: 15 | J23: Vocabulary 3 Grammar 2
B24: LESSON 19 | C24: UNIT 4 MY FAMILY | D24: 30-31 | E24: - Marie's art: Mixing colours - Trevor values: Be kind -(45 minutes) Unit 4 Speaking videoUNIT 4 MY FAMILY, FEELING, COLORS.pptx | F24: What's blue and red? It's purple. | G24: - Students know how to mix colours. - Understand the value of be kind. - Students stand in front of class and read fluently (Teacher records the videos) | I24: 16 | J24: Grammar 3
B25: LESSON 20 | C25: UNIT 4 MY FAMILY | D25: REVIEW + TEST | E25: Review Unit 4 (vocabulary and structures) - Family members - Adjectives | F25: This is my….. He/She is my She is happy He is sad | G25: - Students review all vocabulary and structures | J25: Game 1 and 2
B26: LESSON 21 | C26: UNIT 5 OUR PETS | D26: 34 | E26: - Pets: dog, fish, mouse, cat, bird, horse | F26: - What pet is it? It's a...... | G26: Students understand the topic and remember the words | H26: Video filming: Students take turns to do the Role-play: (Divide the students into pairs) Topic: Do you have a pet? Sample video: Lesson 15_(B)Do you have a pet? - Cartoon Story - English Education - Easy conversation for kids - YouTube (Teacher prepares the Questions list (if needed) ) | I26: 17 | J26: Vocabulary 1
B27: LESSON 22 | C27: UNIT 5 OUR PETS | D27: 35 | E27: - Review pets - Review Adj in Unit 4: Old-young, ugly-beautiful, happy-sad | F27: - It's/ They are.... | G27: Students can use adj to say with pets | I27: 18 | J27: Vocabulary 2 Grammar 1
B28: LESSON 23 | C28: UNIT 5 OUR PETS | D28: 36-37 | E28: - Adjectives: big, small, long, short, clean, dirty - Games online: Adjective practice - Sing a song | F28: - It's/ They are.... | G28: - Student can remember adjectives and use them correctly. - Students can sing a song together | I28: 19 | J28: Vocabulary 3 Grammar 2
B29: LESSON 24 | C29: UNIT 5 OUR PETS | D29: 38-39 | E29: - Pronunciation: /t/ - The story - (45 minutes) Unit 5 Speaking video: Sun 1_Speaking Project_Unit 5.pptx | F29: /t/-/t/- ten, red Ten red pets | G29: - Student learn some words start with /t/ sound in "Say it with Monty". - With the story, make 3 question so students answer them after the story - Students stand in front of class and read fluently (Teacher records the videos) | I29: 20 | J29: Grammar 3
B30: LESSON 25 | C30: UNIT 5 OUR PETS | D30: REVIEW + TEST | E30: Review Unit 5 (vocabulary and structures) - Pets - Adjectives | F30: - What pet is it? It's a...... - It's/ They are.... | G30: - Students review all vocabulary and structures | J30: Game 1 and 2
B31: LESSON 26 | C31: UNIT 6 MY FACE | D31: 40-41 | E31: Parts of face: ear, hair, eye, face, teeth, nose, mouth | F31: - What is this? It's ..... - This is my .... | G31: Students remember the words and use them with structure correctly. | H31: Video filming: Create a face: (Creative Lesson) Draw in a blank face template, create your own face. It could be a boy or a girl, feel free to design every parts of the face then describe about it. Blank template: Blank face Template.jpg | I31: 21 | J31: Vocabulary 1
B32: LESSON 27 | C32: UNIT 6 MY FACE | D32: 42-43 | E32: - Review parts of face - Sing a song | F32: - I have got.... - Have you got....? Yes, I have. /No, I haven't. | G32: - Students can use structure to decribe their parts of face. - Students can sing a song together | I32: 22 | J32: Vocabulary 2 Grammar 1
B33: LESSON 28 | C33: UNIT 6 MY FACE | D33: 44-45 | E33: - Pronunciation: /gt/ and /br/ - The story - Watching videos: + A special shop | F33: /t/-/t/- ten, red Ten red pets | G33: - Student learn some words start with /gr/ and /br/ sound in "Say it with Monty". - With the story, make 3 question so students answer them after the story | I33: 23 | J33: Vocabulary 3 Grammar 2
B34: LESSON 29 | C34: UNIT 6 MY FACE | D34: 46-47 | E34: - Marie's science: hear, see, smell, taste, touch - Do Excercises on page 46-47 (Activity's book) (45 minutes): Unit 6 Speaking video: UNIT 6 PARTS OF FACE, SENSES.pptx | F34: - I see with my eyes. - I hear with my ears. - I smell with my nose. - I taste with my tounge. - I touch with my hands. | G34: - Students remember the words. - Students understand the value. - Students stand in front of class and read fluently (Teacher records the videos) | I34: 24 | J34: Grammar 3
B35: LESSON 30 | C35: UNIT 6 MY FACE | D35: REVIEW | E35: Review Unit 6 (vocabulary and structures) - Parts of face - Senses: see, hear, smell, taste, touch | G35: - Students review all vocabulary and structures | J35: Game 1 and 2
B36: LESSON 31 | C36: REVIEW | D36: 4-17 | E36: Review all vocabularies of Unit 1 and 2 | F36: How old are you? I'm….. What color is it? It's ….. Who is he/she? He/She is... | G36: - Students review the lesson contents of Unit 1 & 2 | J36: Unit 1-2 Game 1 & 2
B37: LESSON 32 | C37: REVIEW | D37: 18-31 | E37: Review all vocabularies of Unit 3 and 4 | F37: What's your favorite toy? Where's the car? This is my mother/father/… | G37: - Students review the lesson contents of Unit 3 & 4 | J37: Unit 3-4 Game 1 & 2
B38: LESSON 33 | C38: REVIEW | D38: 34-47 | E38: Review all vocabularies of Unit 5 and 6 | F38: - It's/They're... - I have got.... - Have you got....? Yes, I have. /No, I haven't. | G38: - Students review the lesson contents of Unit 5 & 6 | J38: Unit 5-6 Game 1 & 2
B39: LESSON 34 | C39: MID-TERM | D39: TEST | E39: MID-TERM TEST - READING, WRITING AND SPEAKING (Speaking test for students whose finish the reading and writing test early. Teachers prepare extra materials for students)
B40: LESSON 35 | C40: MID-TERM | D40: TEST | E40: MID-TERM SPEAKING TEST (Speaking test for students whose aren't finished)
...

Sheet Trang tính3
B4: Grade | C4: SUN 1
B5: LESSONS | C5: LESSON 54
B6: UNITS | C6: =vlookup($C$5,'Sun 1'!$B$6:$J$78,2,0) -> UNIT 10 AT THE FUNFAIR
B7: Student's book & Activity's book pages | C7: =vlookup($C$5,'Sun 1'!$B$6:$J$78,3,0) -> 74-75
B8: Vocabulary Từ vựng | C8: =vlookup($C$5,'Sun 1'!$B$6:$J$78,4,0) -> - Pronunciation: /u/ - The story + Walk around London
B9: Grammar Ngữ pháp | C9: =vlookup($C$5,'Sun 1'!$B$6:$J$78,5,0) -> /u/-duck, under, bus The ducks are under the bus.
B10: Lesson target | C10: =vlookup($C$5,'Sun 1'!$B$6:$J$78,6,0) -> - Student learn some words start with /u/ sound in "Say it with Monty". - With the story, make 3 question so students answer them after the story. - With videos, students can know what they see in London.
B11: Bài tập về nhà Handbook | C11: =vlookup($C$5,'Sun 1'!$B$6:$J$78,8,0) -> 39
B12: E-learning | C12: UNIT 10 VOCABULARY 3 GRAMMAR 2
