Workbook

Sheet Sun 6
A1: SUN-HAPPY TREE 6 SYLLABUS
A2: DATES | B2: LESSONS | C2: UNITS | D2: Student's book PAGES | E2: CONTENTS
E3: Vocabulary | F3: Gramamr/Structures | G3: Lesson target | H3: Homework
H4: Activity book pages | I4: Handbook | J4: E-learning (Assigned by CM)
A5: TERM A (UNIT HELLO THERE! - UNIT 4)
A6: 46120 | B6: 1 | C6: UNIT 0 HIGH TECHNOLOGY | D6: 4-5 | E6: - Introduce the topic, use mind-mapping to explore technology words | F6: - Present simple tense review | G6: - Students can name all technology words as many as they can. (Use mind-mapping) | H6: 4-5 | I6: =B6 -> 1 | J6: Language 1 - 2
A7: 46123 | B7: 2 | C7: UNIT 0 HIGH TECHNOLOGY | D7: 45844 | E7: - Kid's Box reports: Technology screen, headphones, microphone, file, email, upload, app, laptops, tablets, smartphones, online, wi-fi, video games, chat, competition, smart speaker, turn on/off - Activities with song | F7: - Present simple: can and can't - Present simple: have/has got | G7: - Students remember new words. - Students understand the important of technology in our lives. | H7: 45844 | I7: =B7 -> 2 | J7: Vocabulary 1-2 | L7: x
A8: 46127 | B8: 3 | C8: UNIT 0 HIGH TECHNOLOGY | D8: 8-9 | E8: - Sounds: stressed words - Life skills: Being a good school citizen - Story: Diggory bones | F8: We can write ... We have to ... I think it's important to... | G8: - Students practice the pronunciation - Students can ask friends about their techonology things they have got - With the story, make 3 questions so students will answer them after the story | H8: 8-9 | I8: =B8 -> 3 | J8: Reading 1 and 2
A9: 46130 | B9: 4 | C9: UNIT 0 HIGH TECHNOLOGY | D9: REVIEW | E9: Review Unit 0 vocabulary - Technology | F9: - Present simple: have/has got - Present simple: can and can't | G9: - Teachers help students to make speaking structure. - Students can use grammar to talk about their project. | H9: No homework | I9: =B9 -> 4 | J9: Unit 0 Game 1 & 2
A10: 46134 | B10: 5 | C10: UNIT 1 BEASTLY TALES | D10: 10-11 | E10: - Introduce the topic, use mind-mapping to explore animals words. | F10: - Future: be going to | G10: - Students understand the topic - Students can name all TV words as much as they can - Students use grammar correctly. | H10: 10-11 | I10: =B10 -> 5 | J10: Language 1 - 2
A11: 46141 | B11: 6 | C11: UNIT 1 BEASTLY TALES | D11: 12-13 | E11: - Kid's Box reports: Myths + eagle, claws, horn, feathers, scales, dragon, nest, mermaid, griffins, breathe, centaur, unicorn, sirens, harpies - Activity with song. | F11: - Present simple review: have/has got - Relative clauses: Who, where, which | G11: - Students remember new words - Students can name some beasts they know from movie. | H11: 12 | I11: =B11 -> 6 | J11: Vocabulary 1 | L11: x
A12: 46148 | B12: 7 | C12: UNIT 1 BEASTLY TALES | D12: 11 & 13 | E12: Review Kid's Box reports: eagle, claws, horn, feathers, scales, dragon, nest, mermaid, griffins, breathe, centaur, unicorn, sirens, harpies | F12: - Present simple review: have/has got - Relative clauses: Who, where, which | G12: - Students remember new words - Students can name some beasts they know from movie. | H12: 13 | I12: =B12 -> 7 | J12: Vocabulary 2 | L12: x
A13: 46151 | B13: 8 | C13: UNIT 1 BEASTLY TALES | D13: 14-15 | E13: - Sounds: word endings -ing - Life skills: Supporting your friends - Story: Diggory bones | F13: Good luck with ... Go for it! You're good at it! We're right here with you! | G13: - Student learn some words start with /th/ sound. Encourage students to say more words. - With the story, make 3 questions so students will answer them after the story - With writing, students can write at least 20 words. | H13: 14-15 | I13: =B13 -> 8 | J13: Grammar 3 | L13: x
A14: 46155 | B14: 9 | C14: UNIT 1 BEASTLY TALES | D14: 16-17 | E14: - History: toys and games + popular, counters, bone, dice, sides, terracotta, ancient, similar to | F14: Relative clause: Who and which | G14: - Students understand the topic and review the grammar. | H14: 16-17 | I14: =B14 -> 9 | J14: Reading 1 & 2 | L14: x
A15: 46158 | B15: 10 | C15: UNIT 1 BEASTLY TALES | D15: REVIEW & TEST | E15: - Review Unit 1 vocabulary and grammar - Unit 1 paper test | F15: - Present simple review: have/has got - Relative clauses: Who, where, which | G15: - Students can do the test without any assistant - Students can stand in front of class and talk about their favorite TV program. | H15: No homework | I15: =B15 -> 10 | J15: Game 1 & 2
A16: 46162 | B16: 11 | C16: UNIT 2 TOMORROW'S WORLD | D16: 18-19 | E16: - Introduce the topic, use mind-mapping to explore transport words. - Activity with song | F16: - Future: will and won't | G16: - Students understand the topic - Students can name transport words as much as they can - Students can use grammar to talk about their future life. | H16: 18-19 | I16: =B16 -> 11 | J16: Vocabulary 1 Grammar 2
A17: 46165 | B17: 12 | C17: UNIT 2 TOMORROW'S WORLD | D17: 20-21 | E17: - Kid's Box reports: Space Travel space, air, earth, rocket, moon, astronaut, engineer, businessman, tourist, float, transport | F17: - Review future tense: will and won't - Connectors: after that, because, before, then, when | G17: - Students remember new words - Students can say what will they do if they have a space travel | H17: 20 | I17: =B17 -> 12 | J17: Vocabulary 2 | L17: x
A18: 46169 | B18: 13 | C18: UNIT 2 TOMORROW'S WORLD | D18: 18 & 21 | E18: Review Kid's Box reports: Space Travel space, air, earth, rocket, moon, astronaut, engineer, businessman, tourist, float, transport | F18: - Review future tense: will and won't - Connectors: after that, because, before, then, when | G18: - Students remember new words - Students can say what will they do if they have a space travel | H18: 21 | I18: =B18 -> 13 | J18: Grammar 3 | L18: x
A19: 46172 | B19: 14 | C19: UNIT 2 TOMORROW'S WORLD | D19: 22-23 | E19: - Sounds: strong words - Life skills: Choosing a point of view - Story: Diggory bones | F19: In the future, I think we'll .. We won't ... I agree/ I don't agree ... because ... | G19: - Student practice pronunciation with contractions - With the story, make 3 questions so students will answer them after the story - Students can write at least 20 words about their future | H19: 22-23 | I19: =B19 -> 14 | J19: Grammar 1 Vocabulary 3 | L19: x
A20: 46176 | B20: 15 | C20: UNIT 2 TOMORROW'S WORLD | D20: 24-25 | E20: - Physics: Robots + computer technology, produce, perform, surgery, remote surgery, built-in alarm, entertain, robot devices, robot vehicles, research | F20: Learn to write instructions | G20: - Students understand the topic and remember the planets - Students remember the order of planets from the Sun. | H20: 24-25 | I20: =B20 -> 15 | J20: Reading 1 & 2
A21: 46179 | B21: 16 | C21: UNIT 2 TOMORROW'S WORLD | D21: REVIEW & TEST | E21: - Review Unit 2 vocabulary and grammar - Unit 2 paper test | F21: - Review future tense: will and won't - Connectors: after that, because, before, then, when | G21: - Students can do the test without any assistant - Students can stand in front of class and talk about their future jobs. | H21: No homework | I21: =B21 -> 16 | J21: Game 1 & 2
A22: 46183 | B22: 17 | C22: UNIT 3 THE GREAT OURDOOR | D22: 28-29 | E22: - Introduce the topic, use mind-mapping to explore countryside words. - Activity with song | F22: Past continuous - I was jumping over a rock when I fell. - Were you playing when you broke your arm? No, I wasn't playing. | G22: - Students understand the topic - Students can name countryside words as many as they can - Students can use grammar correctly. | H22: 28-29 | I22: =B22 -> 17 | J22: Vocabulary 3 Grammar 2
A23: 46186 | B23: 18 | C23: UNIT 3 THE GREAT OURDOOR | D23: 30-31 | E23: - Kid's Box reports: explorers + north, south, east, west, explorer, tent, torch, rucksack, sleeping bag, camp, flashlight, adventures, journey - Writing: Write an adventure | F23: Review Past continuous | G23: - Students remember new words - Students know famous explorers in the world - Students finish writing activity | H23: 30 | I23: =B23 -> 18 | J23: Vocabulary 1 | L23: x
A24: 46190 | B24: 19 | C24: UNIT 3 THE GREAT OURDOOR | D24: 28 & 31 | E24: - Review countryside words - Review Kid's Box reports: explorers + north, south, east, west, explorer, tent, torch, rucksack, sleeping bag, camp, flashlight, adventures, journey | F24: Review Past continuous | G24: - Students remember new words - Students know famous explorers in the world - Students finish writing activity | H24: 31 | I24: =B24 -> 19 | J24: Grammar 1 | L24: x
A25: 46193 | B25: 20 | C25: UNIT 3 THE GREAT OURDOOR | D25: 32-33 | E25: - Sounds: /b/, /v/ and /w/ sounds - Life skills: Imagining posibilities - Story: Diggory bones | F25: Past simple and past continuous | G25: - Student practice consonant sound 'k' - With the story, make 3 questions so students will answer them after the story - Students can write at least 20 words in writing exercise - Students understand the topic of video | H25: 32-33 | I25: =B25 -> 20 | J25: Reading 1 and 2 | L25: x
B26: 21 | C26: UNIT 3 THE GREAT OURDOOR | D26: 34-35 | E26: - Geography: mountains + landform, high above, mountain range, plates, mountain rage, plates, Earth's crust, forming, peak | F26: Like + ing to talk about what we enjoy Would like + infinitive to talk about what we want to do | G26: - Students understand the topic and the different between lanscape painting with others. | H26: 34-35 | I26: =B26 -> 21 | J26: Vocabulary 2 Grammar 3 | L26: x
B27: 22 | C27: UNIT 3 THE GREAT OURDOOR | D27: REVIEW & TEST | E27: - Review Unit 3 vocabulary and grammar - Unit 3 paper test | F27: Past continuous - I was jumping over a rock when I fell. - Were you playing when you broke your arm? No, I wasn't playing. | G27: - Students can do the test without any assistant - Students can stand in front of class and talk about their famous artist | H27: No homework | I27: =B27 -> 22 | J27: Game 1 and 2
A28: 46204 | B28: 23 | C28: UNIT 4 FOOD, GLORIOUS FOOD | D28: 36-37 | E28: - Introduce the topic, use mind-mapping to explore food words. | F28: - Enough/ Too many/ too much - Future and present perfect tense | G28: - Students understand the topic - Students can name food words as many as they can - Students can use grammar correctly. | H28: 36-37 | I28: =B28 -> 23 | J28: Language 1 - 2
A29: 46207 | B29: 24 | C29: UNIT 4 FOOD, GLORIOUS FOOD | D29: 38-39 | E29: - Review food words - Kid's Box reports: Food + Sushi, dish, chopsticks, pizza, pasta, sauce, paella, pan, snack, popcorn, butter, biscuits, fruit, jam, peanuts | F29: - Use enough/too many and there is/are with countable and uncountable nouns. | G29: - Students remember new words - Students know how to make food of the lesson. | H29: 38 | I29: =B29 -> 24 | J29: Vocabulary 1-2 | L29: x
A30: 46211 | B30: 25 | C30: UNIT 4 FOOD, GLORIOUS FOOD | D30: 36 & 39 | E30: - Review food words - Review Kid's Box reports: Food + Sushi, dish, chopsticks, pizza, pasta, sauce, paella, pan, snack, popcorn, butter, biscuits, fruit, jam, peanuts | F30: - Use enough/too many and there is/are with countable and uncountable nouns. | G30: - Students remember new words - Students know how to make food of the lesson. | H30: 39 | I30: =B30 -> 25 | J30: A2 Flyers + Values | L30: x
A31: 46214 | B31: 26 | C31: UNIT 4 FOOD, GLORIOUS FOOD | D31: 40-41 | E31: - Sounds: strong words - Life skills: Exploring food from other cultures - Story: Diggory bones | F31: So let's ... Where is/are ... from? If you want, we can ... Cool, why not? | G31: - Student practice /gh/ sound - With the story, make 3 questions so students will answer them after the story - Students can write at least 20 words in writing exercise - Students understand how to make food in the video | H31: 40-41 | I31: =B31 -> 26 | J31: Sound and Life Skills Story | L31: x
A32: 46218 | B32: 27 | C32: UNIT 4 FOOD, GLORIOUS FOOD | D32: 42-43 | E32: - Biology: apples + raw, vitamins, minerals, skin, mild, orchard, seeds, polimate, harvest time | F32: Learn to write sequencing words | G32: - Students understand the topic - Students know how to keep food in safe condition. | H32: 42-43 | I32: =B32 -> 27 | J32: CLIL: biology | L32: x
A33: 46221 | B33: 28 | C33: UNIT 4 FOOD, GLORIOUS FOOD | D33: REVIEW & TEST | E33: - Review Unit 4 vocabulary and grammar - Unit 4 paper test | F33: - Enough/ Too many - Future and present perfect tense - Use enough/too many and there is/are with countable and uncountable nouns. | G33: - Students can do the test without any assistant - Students understand the value of lesson - Students can stand in front of class and talk about their favourite food. | H33: No homework | I33: =B33 -> 28 | J33: Review + Game
A34: 46225 | B34: 29 | C34: REVIEW UNIT 1 | D34: 10-17 | E34: Review Unit 1 vocabulary - Animals - Myth legends | F34: - Present simple review: have/has got - Relative clauses: Who, where, which | G34: Students review for the mid-term test | H34: No homework | I34: =B34 -> 29 | J34: Unit 1 Review + Game
A35: 46228 | B35: 30 | C35: REVIEW UNIT 2 | D35: 18-27 | E35: Review Unit 2 vocabulary - Space travel - Solar system | F35: - Review future tense: will and won't - Connectors: after that, because, before, then, when | G35: Students review for the mid-term test | H35: No homework | I35: =B35 -> 30 | J35: Unit 2 Review + Game
A36: 46232 | B36: 31 | C36: REVIEW UNIT 3 | D36: 28-35 | E36: Review Unit 3 vocabulary - Explorers | F36: Past continuous - I was jumping over a rock when I fell. - Were you playing when you broke your arm? No, I wasn't playing. | G36: Students review for the mid-term test | H36: No homework | I36: =B36 -> 31 | J36: Unit 3 Review + Game
A37: 46235 | B37: 32 | C37: REVIEW UNIT 4 | D37: 36-43 | E37: Review Unit 4 vocabulary - Food | F37: - Enough/ Too many - Future and present perfect tense - Use enough/too many and there is/are with countable and uncountable nouns. | G37: Students review for the mid-term test | H37: No homework | I37: =B37 -> 32 | J37: Unit 4 Review + Game
B38: 33 | C38: TEST | E38: MIDTERM TEST - LISTENING, READING, WRITING (For Listening, each part will be listened in 2 times) | G38: - Teachers instruct students what to do in each part of the paper test - Teachers prepare worksheets for students to do in class if they finish early - Teachers also can do speaking test for students while they're doing the worksheets | H38: No homework | I38: =B38 -> 33
B39: 34 | C39: TEST | E39: MIDTERM TEST - SPEAKING (See the speaking instruction in Test Answer Key) | G39: - Teachers prepare worksheets for students to do in class - Teachers instruct students what to do in each part of the speaking test - Teachers complete the speaking test for all students | H39: No homework | I39: =B39 -> 34
B40: 35 | C40: YLE PRACTICE | D40: Link | E40: EXTRA BOOK: FUN FOR FLYERS (Unit 29-35) | G40: - Students practice Flyers Cambridge exam - Teachers ask students to open Handbook | H40: No homework | I40: No homework
...

Sheet Trang tính3
B4: Grade | C4: Cột 2
B5: LESSONS | C5: 1
B6: UNITS | C6: =vlookup($C$5,'Sun 6'!B:J,2,0) -> UNIT 0 HIGH TECHNOLOGY
B7: Student's book & Activity's book pages | C7: =vlookup($C$5,'Sun 6'!B:J,3,0) -> 4-5
B8: Vocabulary Từ vựng | C8: =vlookup($C$5,'Sun 6'!B:J,4,0) -> - Introduce the topic, use mind-mapping to explore technology words
B9: Structures Cấu trúc câu/ Ngữ pháp | C9: =vlookup($C$5,'Sun 6'!B:J,5,0) -> - Present simple tense review
C10: =vlookup($C$5,'Sun 6'!B:J,2,0) -> UNIT 0 HIGH TECHNOLOGY
B11: Homework Handbook | C11: =vlookup($C$5,'Sun 6'!B:J,6,0) -> - Students can name all technology words as many as they can. (Use mind-mapping)
B12: E-learning | C12: =vlookup($C$5,'Sun 6'!B:J,7,0) -> 4-5
