Workbook

Sheet Sun 3 old
A1: SUN 3 SYLLABUS
A2: DATES | C2: UNITS | D2: Student's book PAGES | E2: CONTENTS | J2: Materials
E3: Vocabulary | F3: Structures/Grammar | G3: Lesson target | H3: Homework
H4: Activity book pages (Assigned by teachers) | I4: E-learning (Assigned by CM)
A5: TERM A (UNIT HELLO! - UNIT 4)
B6: LESSON 1 | C6: UNIT 0 HELLO! | D6: 4-5 | E6: - Introduce characters: Simon, Suzy, Stella, Mr. Star, Mrs. Star, Grandma Star, Grandpa Star, Lenny, Alex, Meera - Story characters: Lock and Key | F6: - What's your name? - How old are you? - Have you got a brother or a sister? - What's your favorite toy called? | G6: - Students can introduce themsleves with simple sentences - Students remember the characters | H6: 4-5 | I6: Vocabulary 1 & 2
B7: LESSON 2 | C7: UNIT 0 HELLO! | D7: 6 | E7: - Review characters - Reading: At school | F7: - Present continuous - What's Suzy doing? She is jumping. | G7: - Students review the characters. - Students practice and use grammar correctly | H7: 6 | I7: Vocabulary 3 Grammar 2
B8: LESSON 3 | C8: UNIT 0 HELLO! | D8: 7 | E8: - Names: Mary, Sally, Paul, Fred, Jim, Vicky. - Sing a song | F8: - Review present continuous - I've got…. | G8: - Students review the grammar. - Students can sing a song together. | H8: 7 | I8: Grammar 1 & 3
B9: LESSON 4 | C9: UNIT 0 HELLO! | D9: 8-9 | E9: - Stella's phonics: Rhyming words - Activities: ride a bike, play badminton, swim, play the piano, sing, play football. - Story: Lock and Key | F9: - /o/ - Hello, yellow - /e/ - Red, head - /i/ - Clean, green - Can you (ride a bike)? + Yes, I can./ No, I can't. - Present continuous | G9: - Student learn some words start with /j/ and /ch/ sound. Encourage students to say more words. - With the story, make 3 questions so students will answer them after the story | H9: 8-9 | I9: Reading 1 & 2
B10: LESSON 5 | C10: UNIT 0 HELLO! | D10: REVIEW | E10: Review Unit 0 vocabulary - Characters - Activities | F10: - What's your name? - How old are you? - Have you got a brother or a sister? - What's your favorite toy called? - What's Suzy doing? She is jumping. | G10: Students review the vocabulary and structures | H10: Unit 0 Home booklet | I10: Unit 0 Game 1 & 2
B11: LESSON 6 | C11: UNIT 1 FAMILY MATTERS | D11: 10-11 | E11: - Family members: aunt, daughter, granddaughter, grandson, grandparents, son, uncle. - Actions: Playing a game, reading, playing football, painting, taking a photo. | F11: - Who is Stella's uncle? - Who is Suzy's aunt? - Suzy's sitting next to her mother. | G11: - Students understand the family tree and know how to recognize their family members. - Students can use present continuous to talk about family. | H11: 10-11 | I11: Vocabulary 1 & 2
B12: LESSON 7 | C12: UNIT 1 FAMILY MATTERS | D12: 12-13 | E12: - Review family members - Reading: Aunt May - Sing a song | F12: - Enjoy + V-ing - Want + to V | G12: - Students know when to use "enjoy" and "want". - Students can draw their family tree. - Students can sing a song together. | H12: 12 | I12: Vocabulary 3
B13: LESSON 8 | C13: UNIT 1 FAMILY MATTERS | D13: 12-13 | E13: - Review family members - Reading: Aunt May - Sing a song | F13: - Enjoy + V-ing - Want + to V | G13: - Students know when to use "enjoy" and "want". - Students can draw their family tree. - Students can sing a song together. | H13: 13 | I13: Grammar 1
B14: LESSON 9 | C14: UNIT 1 FAMILY MATTERS | D14: 14-15 | E14: - Stella's phonics: Long vowel sounds: "ay" and "ar" - Story: Lock and Key - Writing: Write about friend's hobbies - Watch a video: + Kid's Box Art show. | F14: - Present simple: Questions form Do you like playing on your laptop? Yes, I do./ No, I don't. | G14: - Student learn some words start with /ay/ and /ar/ sounds. Encourage students to say more words. - With the story, make 3 questions so students will answer them after the story - With writing, students can write at least 15 words. | H14: 14-15 | I14: Grammar 2 Reading 1
B15: LESSON 10 | C15: UNIT 1 FAMILY MATTERS | D15: 16-17 | E15: - Art: Portraits Oil paintings, artist, self-portrait | F15: - Like and love - Present continuous review | G15: - Students understand the topic and review the grammar. | H15: 16-17 | I15: Reading 2 Grammar 3
B16: LESSON 11 | C16: UNIT 1 FAMILY MATTERS | D16: REVIEW | E16: -Review Unit 1 vocabulary - Unit 1 test - Unit 1 Speaking video (link) | F16: - Who is Stella's uncle? - Who is Suzy's aunt? - Enjoy + V-ing - Want + to V | G16: Students review the vocabulary and structures | H16: Unit 1 Home booklet | I16: Unit 1 Game 1 & 2
B17: LESSON 12 | C17: UNIT 2 HOME SWEET HOME | D17: 18-19 | E17: - Houses: upstairs, downstairs, stairs, basement - Flat: lift, balcony - Places: village, town, house, flat. - Sing a song | F17: - My house has got a basement. - My flat hasn't got three bedrooms. | G17: - Students remember new words - Students understand the differences between house and flat. - Students can use grammar to talk about their house/flat. - Students can sing a song together. | H17: 18-19 | I17: Vocabulary 1 & 3
B18: LESSON 13 | C18: UNIT 2 HOME SWEET HOME | D18: 20-21 | E18: - Review the vocabulary - Reading: Meera moves to a new flat. - Numbers: 12 to 100 | F18: - Present continuous - Present simple: Talk about address - What's your address? It's 72 Station Road. | G18: - Students review the numbers. - Students can use numbers to talk about their house/falt address. | H18: 20 | I18: Vocabulary 2
B19: LESSON 14 | C19: UNIT 2 HOME SWEET HOME | D19: 20-21 | E19: - Review the vocabulary - Reading: Meera moves to a new flat. - Numbers: 12 to 100 | F19: - Present continuous - Present simple: Talk about address - What's your address? It's 72 Station Road. | G19: - Students review the numbers. - Students can use numbers to talk about their house/falt address. | H19: 21 | I19: Grammar 2
B20: LESSON 15 | C20: UNIT 2 HOME SWEET HOME | D20: 22-23 | E20: - Stella's phonics: Long vowel sounds: "oa" and "ou". - Story: Lock and Key - Writing: Make a contact table | F20: - What's your name? - Where do you live? - What's your address? - What's your phone number? | G20: - Student learn some words start with 'oa' and 'ou' sounds. Encourage students to say more words. - With the story, make 3 questions so students will answer them after the story | H20: 22-23 | I20: Reading 1 & 2
B21: LESSON 16 | C21: UNIT 2 HOME SWEET HOME | D21: 24-25 | E21: - Geography: Homes garden, lift, shops, tree, flower, big, car, bird, small, lorry, street. | F21: - I'd like to live in a castle because it's got a big garden. | G21: - Students understand the topic. - Students can talk about their places they want to live and explain the reason. | H21: 24-25 | I21: Grammar 1 & 3
B22: LESSON 17 | C22: UNIT 2 HOME SWEET HOME | D22: REVIEW | E22: -Review Unit 2 vocabulary - Unit 2 test - Unit 2 Speaking video (link) | F22: - Present continuous - Present simple: Talk about address - What's your address? It's 72 Station Road. | G22: Students review the vocabulary and structures | H22: Unit 2 Home booklet | I22: Unit 2 Game 1 & 2
B23: LESSON 18 | C23: UNIT 3 A DAY IN THE LIFE | D23: 28-29 | E23: - Routines: get dressed/ undressed, get up, go to bed, have a shower, put on, wake up, take off, wash, catch the bus, do homework - Sing a song activity | F23: - What time does she wake up? She wakes up at seven o'clock. - What do you do before/after breakfast? | G23: - Students understand the topic and remember the vocabulary. - Students can talk aout their daily routines. - Students can sing a song together. | H23: 28-29 | I23: Vocabulary 1 & 2
B24: LESSON 19 | C24: UNIT 3 A DAY IN THE LIFE | D24: 30-31 | E24: - Review routines - Days of the week - Adverbs: always, sometimes, never | F24: - He never plays in the park on Monday. - I always ride my bike on Tuesday. | G24: - Students can use adverbs to talk about their daily routines | H24: 30 | I24: Vocabulary 3
B25: LESSON 20 | C25: UNIT 3 A DAY IN THE LIFE | D25: 30-31 | E25: - Review routines - Days of the week - Adverbs: always, sometimes, never | F25: - He never plays in the park on Monday. - I always ride my bike on Tuesday. | G25: - Students can use adverbs to talk about their daily routines | H25: 31 | I25: Grammar 1
B26: LESSON 21 | C26: UNIT 3 A DAY IN THE LIFE | D26: 32-33 | E26: - Stella's phonics: Long vowel sounds: /or/ - Story: Lock and Key - Writing: Answer the questions on page 32 - Watch a video + At the fire station. | F26: How often do you....? I always/sometimes/never/...... | G26: - Student learn some words start with 'oa' and 'ou' sounds. Encourage students to say more words. - With the story, make 3 questions so students will answer them after the story | H26: 32-33 | I26: Grammar 2 & 3
B27: LESSON 22 | C27: UNIT 3 A DAY IN THE LIFE | D27: 34-35 | E27: - Science: The heart + heart beat, blood from/to the body/lúng, oxygen, pulse, quick, slow | F27: Present simpe tense | G27: - Students understand the operation of heart and how to take their pulse quick or slow. | H27: 34-35 | I27: Reading 1 & 2
B28: LESSON 23 | C28: UNIT 3 A DAY IN THE LIFE | D28: REVIEW | E28: -Review Unit 3 vocabulary - Unit 3 test - Unit 3 Speaking video (link) | F28: - What time does she wake up? She wakes up at seven o'clock. - What do you do before/after breakfast? How often do you....? I always/sometimes/never/...... | G28: Students review the vocabulary and structures | H28: Unit 3 Home booklet | I28: Unit 3 Game 1 & 2
B29: LESSON 24 | C29: UNIT 4 IN THE CITY | D29: 36-37 | E29: - In town: bank, bus station, cinema, sports centre, supermarket, swimming pool, library, market. - Prepositions: in front of, behind, next to, between, opposite. | F29: - Where is it? It's a... - What's opposite the cinema? It's the..... - Where is the ...? It's.... | G29: - Students understand the topic and know what they often do in particular places. - Students can use prepositions to find the location. | H29: 36 | I29: Vocabulary 2
B30: LESSON 25 | C30: UNIT 4 IN THE CITY | D30: 36-37 | E30: Review - In town: bank, bus station, cinema, sports centre, supermarket, swimming pool, library, market. - Prepositions: in front of, behind, next to, between, opposite. | F30: - Where is it? It's a... - What's opposite the cinema? It's the..... - Where is the ...? It's.... | G30: - Students understand the topic and know what they often do in particular places. - Students can use prepositions to find the location. | H30: 37 | I30: Grammar 1
B31: LESSON 26 | C31: UNIT 4 IN THE CITY | D31: 38-39 | E31: - Review places in town - Sing a song activity | F31: - Sentences with "must" | G31: - Students understand what they must do in particular places. | H31: 38-39 | I31: Vocabulary 1 Grammar 2
B32: LESSON 27 | C32: UNIT 4 IN THE CITY | D32: 40-41 | E32: - Stella's phonics: consonant sounds: /s/ - Story: Lock and Key | F32: - Can Sam play tennis on Friday? No, he must go to the doctor on Friday. | G32: - Student learn some words start with /s/ sounds. Encourage students to say more words. - With the story, make 3 questions so students will answer them after the story | H32: 40-41 | I32: Reading 1 & 2
B33: LESSON 28 | C33: UNIT 4 IN THE CITY | D33: 42-43 | E33: - Maths: Counting money Pence, pound, coin | F33: - How much are the pens? They are 75p. | G33: - Students undertand the currency in Britain. - Students know how to say the price of things. | H33: 42-43 | I33: Grammar 3 Vocabulary 3
B34: LESSON 29 | C34: UNIT 4 IN THE CITY | D34: REVIEW | E34: - Review Unit 4 vocabulary - Unit 4 test - Unit 4 Speaking video (link) | F34: - Where is it? It's a... - What's opposite the cinema? It's the..... - Where is the ...? It's.... | G34: Students review the vocabulary and structures | H34: Unit 4 Home booklet | I34: Unit 4 Game 1 & 2
B35: LESSON 30 | C35: REVIEW UNIT 1 | D35: 10-17 | E35: Review Unit 1 vocabulary - Family members - Actions | F35: - Who is Stella's uncle? - Who is Suzy's aunt? - Enjoy + V-ing - Want + to V | G35: Students review for the mid-term test | H35: Home Fun 3 Topic 1: Animals | I35: Unit 1 Game 1 & 2 | J35: Link
B36: LESSON 31 | C36: REVIEW UNIT 2 | D36: 18-27 | E36: Review Unit 2 vocabulary - House and places - Numbers: 10-100 | F36: - Present continuous - Present simple: Talk about address - What's your address? It's 72 Station Road. | G36: Students review for the mid-term test | H36: Home Fun 3 Topic 2: Places | I36: Unit 2 Game 1 & 2 | J36: Link
B37: LESSON 32 | C37: REVIEW UNIT 3 | D37: 28-35 | E37: Review Unit 3 vocabulary - Routines - Days of the week - Adverbs | F37: - What time does she wake up? She wakes up at seven o'clock. - What do you do before/after breakfast? How often do you....? I always/sometimes/never/...... | G37: Students review for the mid-term test | H37: Home Fun 3 Topic 3: Home Topic 4: Sport and leisure | I37: Unit 3 Game 1 & 2 | J37: Link
B38: LESSON 33 | C38: TEST | E38: END OF TERM A TEST - READING, WRITING (Teachers prepare worksheets for students to do in class if they finish early)
B39: LESSON 34 | C39: TEST | E39: END OF TERM A SPEAKING TEST (Teachers prepare worksheets for students to do in class)
B40: LESSON 35 | C40: YLE PRACTICE | E40: PRACTICE MOVERS EXERCISES - FUN FOR MOVERS (Unit 1-6) (See the attachment to prepare for lessons) | J40: Link
...

Sheet Sun 3
A1: SUN 3 SYLLABUS
A2: DATES | B2: LESSONS | C2: UNITS | D2: Student's book PAGES | E2: CONTENTS
E3: Vocabulary | F3: Structures/Grammar | G3: Lesson target | H3: Homework
H4: Activity book | I4: Handbook | J4: E-learning (Assigned by CM)
A5: TERM A (UNIT HELLO! - UNIT 4)
A6: 46245 | B6: 1 | C6: UNIT 0 HELLO! | D6: 4-5 | E6: - Introduce characters: Simon, Suzy, Stella, Mr. Star, Mrs. Star, Grandma Star, Grandpa Star, Lenny, Alex, Meera - Story characters: Lock and Key - Numbers: 11 to 20 | F6: - What's your name? - How old are you? - Have you got a brother or a sister? - What's your favorite toy called? | G6: - Students can introduce themsleves with simple sentences - Students remember the characters | H6: 4-5 | I6: =B6 -> 1 | J6: Vocabulary 1 & 2
A7: 46248 | B7: 2 | C7: UNIT 0 HELLO! | D7: 45844 | E7: - Review characters - Reading: At school - Sing a song | F7: - Present continuous - What's Suzy doing? She is jumping. - I've got…. | G7: - Students review the characters. - Students practice and use grammar correctly - Students can sing a song together. | H7: 45844 | I7: =B7 -> 2 | J7: Vocabulary 3 Grammar 1-3
A8: 46252 | B8: 3 | C8: UNIT 0 HELLO! | D8: 8-9 | E8: - Sounds and spelling: i-e, y, ay, ai, ei, a-e, ey - Activities: ride a bike, play badminton, swim, play the piano, sing, play football. - Story: Lock and Key | F8: The spiders ride, fly and drive from nine to five They play and paint from eight to late. - Can you (ride a bike)? + Yes, I can./ No, I can't. - Present continuous | G8: - Student learn some words start with /j/ and /ch/ sound. Encourage students to say more words. - With the story, make 3 questions so students will answer them after the story | H8: 8-9 | I8: =B8 -> 3 | J8: Reading 1 & 2
A9: 46255 | B9: 4 | C9: UNIT 0 HELLO! | D9: REVIEW + SPEAKING PROJECT | E9: Review Unit 0 vocabulary - Characters - Activities Speaking Project: Unit 0 Speaking Project | F9: - What's your name? - How old are you? - Have you got a brother or a sister? - What's your favorite toy called? - What's Suzy doing? She is jumping. | G9: Students review the vocabulary and structures | H9: No homework | I9: =B9 -> 4 | J9: Unit 0 Game 1 & 2
A10: 46259 | B10: 5 | C10: UNIT 1 FAMILY MATTERS | D10: 10-11 | E10: - Family members: aunt, daughter, granddaughter, grandson, grandparents, son, uncle. - Actions: Playing a game, reading, playing football, painting, taking a photo. | F10: - Who is Stella's uncle? - Who is Suzy's aunt? - Present continuous review | G10: - Students understand the family tree and know how to recognize their family members. - Students can use present continuous to talk about family. | H10: 10-11 | I10: =B10 -> 5 | J10: Vocabulary 1 & 2
A11: 46262 | B11: 6 | C11: UNIT 1 FAMILY MATTERS | D11: 12-13 | E11: - Reading: Aunt May - Sing a song | F11: - Enjoy + V-ing - Want + to V | G11: - Students know when to use "enjoy" and "want". - Students can sing a song together. | H11: 12 | I11: =B11 -> 6 | J11: Vocabulary 3
A12: 46266 | B12: 7 | C12: UNIT 1 FAMILY MATTERS | D12: 10 & 13 | E12: Review Family members: aunt, daughter, granddaughter, grandson, grandparents, son, uncle | F12: - Who is Stella's uncle? - Who is Suzy's aunt? - Enjoy + V-ing - Want + to V | G12: - Students review family members and use vocabulary to describe family tree - Students review enjoy and want to talk/write about their family | H12: 13 | I12: =B12 -> 7 | J12: Grammar 1
B13: 8 | C13: UNIT 1 FAMILY MATTERS | D13: 14-15 + SPEAKING PROJECT | E13: ''- Sounds and spelling: er - Story: Lock and Key Speaking Project: Unit 1_Speaking Project_Family Matters.pptx | F13: Bread, butter, burgers - What's for dinner? Father, mother, brother and sister love making dinner | G13: - Student learn some words start with /ay/ and /ar/ sounds. Encourage students to say more words. - With the story, make 3 questions so students will answer them after the story - With writing, students can write at least 15 words. | H13: 14-15 | I13: =B13 -> 8 | J13: Grammar 2 Reading 1
B14: 9 | C14: UNIT 1 FAMILY MATTERS | D14: 16-17 | E14: Math: Measuring - Math function: Addition, subtraction, multiplication, division - Symbol: plus, minus, times, divided by, equals, is greater than, is less than | F14: How tall am I? How long is my foot? How wide is my hand? How wide is my English book? How long is my hair? | G14: Students understand the topic and review the grammar. | H14: 16-17 | I14: =B14 -> 9 | J14: Reading 2 Grammar 3
B15: 10 | C15: UNIT 1 FAMILY MATTERS | D15: REVIEW & TEST | E15: - Review Unit 1 vocabulary and grammar - Unit 1 paper test | F15: - Who is Stella's uncle? - Who is Suzy's aunt? - Enjoy + V-ing - Want + to V | G15: Students review the vocabulary and structures | H15: No homework | I15: =B15 -> 10 | J15: Unit 1 Game 1 & 2
B16: 11 | C16: UNIT 2 HOME SWEET HOME | D16: 18-19 | E16: - Houses: upstairs, downstairs, stairs, basement - Flat: lift, balcony - Places: village, town, house, flat. - Sing a song | F16: - My house has got a basement. - My flat hasn't got three bedrooms. | G16: - Students remember new words - Students understand the differences between house and flat. - Students can use grammar to talk about their house/flat. - Students can sing a song together. | H16: 18-19 | I16: =B16 -> 11 | J16: Vocabulary 1 & 3
B17: 12 | C17: UNIT 2 HOME SWEET HOME | D17: 20-21 | E17: - Reading: Meera moves to a new flat. - Numbers: 12 to 100 | F17: - Present continuous - Present simple: Talk about address - What's your address? It's 72 Station Road. | G17: - Students review the numbers. - Students can use numbers to talk about their house/falt address. | H17: 20 | I17: =B17 -> 12 | J17: Vocabulary 2
B18: 13 | C18: UNIT 2 HOME SWEET HOME | D18: 18 & 21 | E18: Review - Houses: upstairs, downstairs, stairs, basement - Flat: lift, balcony - Places: village, town, house, flat. - Numbers: 12 to 100 | F18: - My house has got a basement. - My flat hasn't got three bedrooms. - What's your address? It's 72 Station Road. | G18: - Students review the numbers. - Students can use numbers to talk about their house/falt address. | H18: 21 | I18: =B18 -> 13 | J18: Grammar 2
B19: 14 | C19: UNIT 2 HOME SWEET HOME | D19: 22-23 + SPEAKING PROJECT | E19: ''- Sounds and spelling: ee - Story: Lock and Key Speaking Project: Unit 2_Speaking Project_Home sweet home .pptx | F19: See the street where we meet. Bees at number three and sheep at number thirteen Green trees in between | G19: - Student learn some words start with 'oa' and 'ou' sounds. Encourage students to say more words. - With the story, make 3 questions so students will answer them after the story | H19: 22-23 | I19: =B19 -> 14 | J19: Reading 1 & 2
B20: 15 | C20: UNIT 2 HOME SWEET HOME | D20: 24-25 | E20: - Geography: Different types homes cabins, stilts, flat, spiral staircases, cave home, houseboat, tree house, rope bridge | F20: How to use contractions | G20: - Students understand the topic. - Students can talk about their places they want to live and explain the reason. | H20: 24-25 | I20: =B20 -> 15 | J20: Grammar 1 & 3
B21: 16 | C21: UNIT 2 HOME SWEET HOME | D21: REVIEW & TEST | E21: - Review Unit 2 vocabulary and grammar - Unit 2 paper test | F21: - Present continuous - Present simple: Talk about address - What's your address? It's 72 Station Road. | G21: Students review the vocabulary and structures | H21: No homework | I21: =B21 -> 16 | J21: Unit 2 Game 1 & 2
B22: 17 | C22: UNIT 3 A DAY IN THE LIFE | D22: 28-29 | E22: - Routines: get dressed/ undressed, get up, go to bed, have a shower, put on, wake up, take off, wash, catch the bus, do homework - Sing a song activity | F22: - What time does she wake up? She wakes up at seven o'clock. - What do you do before/after breakfast? | G22: - Students understand the topic and remember the vocabulary. - Students can talk aout their daily routines. - Students can sing a song together. | H22: 28-29 | I22: =B22 -> 17 | J22: Vocabulary 1 & 2
B23: 18 | C23: UNIT 3 A DAY IN THE LIFE | D23: 30-31 | E23: - Review routines - Days of the week - Adverbs: always, sometimes, never | F23: - He never plays in the park on Monday. - I always ride my bike on Tuesday. | G23: Students understand the differences between adverbs | H23: 30 | I23: =B23 -> 18 | J23: Vocabulary 3
B24: 19 | C24: UNIT 3 A DAY IN THE LIFE | D24: 28 & 31 | E24: Review Routines: get dressed/ undressed, get up, go to bed, have a shower, put on, wake up, take off, wash, catch the bus, do homework | F24: Review adverbs: always, sometimes, never | G24: Students can use vocabulary and adverbs to talk about their daily routines | H24: 31 | I24: =B24 -> 19 | J24: Grammar 1
B25: 20 | C25: UNIT 3 A DAY IN THE LIFE | D25: 32-33 + SPEAKING PROJECT | E25: ''- Sounds and spelling: /iz/, /s/, /z/ - Story: Lock and Key Speaking Project: Unit 3_Speaking Project_A day in the life .pptx | F25: Owl dances at night and plays by the moon. He catches his food and eat before noon. | G25: - Student learn some words start with 'oa' and 'ou' sounds. Encourage students to say more words. - With the story, make 3 questions so students will answer them after the story | H25: 32-33 | I25: =B25 -> 20 | J25: Grammar 2 & 3
B26: 21 | C26: UNIT 3 A DAY IN THE LIFE | D26: 34-35 | E26: - Science: Astronauts in space - Reading: My first spacewalk | F26: Learning to write times | G26: - Students understand the operation of heart and how to take their pulse quick or slow. | H26: 34-35 | I26: =B26 -> 21 | J26: Reading 1 & 2
B27: 22 | C27: UNIT 3 A DAY IN THE LIFE | D27: REVIEW & TEST | E27: - Review Unit 3 vocabulary and grammar - Unit 3 paper test | F27: - What time does she wake up? She wakes up at seven o'clock. - What do you do before/after breakfast? How often do you....? I always/sometimes/never/...... | G27: Students review the vocabulary and structures | H27: No homework | I27: =B27 -> 22 | J27: Unit 3 Game 1 & 2
B28: 23 | C28: UNIT 4 IN THE CITY | D28: 36-37 | E28: - In town: bank, bus station, cinema, sports centre, supermarket, swimming pool, library, market. - Prepositions: in front of, behind, next to, between, opposite. | F28: - Where is it? It's a... - What's opposite the cinema? It's the..... - Where is the ...? It's.... | G28: - Students understand the topic and know what they often do in particular places. - Students can use prepositions to find the location. | H28: 36-37 | I28: =B28 -> 23 | J28: Vocabulary 2
B29: 24 | C29: UNIT 4 IN THE CITY | D29: 38-39 | E29: - Review places in town - Sing a song activity | F29: Must/musn't | G29: - Students understand what they must do in particular places. | H29: 38 | I29: =B29 -> 24 | J29: Grammar 1
B30: 25 | C30: UNIT 4 IN THE CITY | D30: 36 & 39 | E30: Review places in town and prepositions | F30: - What's opposite the cinema? It's the..... - Where is the ...? It's.... - Sentences with must/mustn't | G30: Students can use prepositions to talk about places in a map Students can use must/musn't to talk/write what they do at different places | H30: 39 | I30: =B30 -> 25 | J30: Vocabulary 1 Grammar 2
B31: 26 | C31: UNIT 4 IN THE CITY | D31: 40-41 + SPEAKING PROJECT | E31: ''- Sounds and spelling: ere, ear, air - Story: Lock and Key Speaking Project: Unit 4_Speaking Project_In the city.pptx | F31: Where's the bear with purple chair? He's over there, on the chair! | G31: - Student learn some words start with /s/ sounds. Encourage students to say more words. - With the story, make 3 questions so students will answer them after the story | H31: 40-41 | I31: =B31 -> 26 | J31: Reading 1 & 2
B32: 27 | C32: UNIT 4 IN THE CITY | D32: 42-43 | E32: - Geography: Shopping - Different types of shop | F32: Learn about Noun | G32: - Students undertand the currency in Britain. - Students know how to say the price of things. | H32: 42-43 | I32: =B32 -> 27 | J32: Grammar 3 Vocabulary 3
B33: 28 | C33: UNIT 4 IN THE CITY | D33: REVIEW & TEST | E33: - Review Unit 4 vocabulary and grammar - Unit 4 paper test | F33: - Where is it? It's a... - What's opposite the cinema? It's the..... - Where is the ...? It's.... | G33: Students review the vocabulary and structures | H33: No homework | I33: =B33 -> 28 | J33: Unit 4 Game 1 & 2
B34: 29 | C34: REVIEW UNIT 1 | D34: 10-17 | E34: Review Unit 1 vocabulary - Family members - Actions | F34: - Who is Stella's uncle? - Who is Suzy's aunt? - Enjoy + V-ing - Want + to V | G34: Students review for the mid-term test | H34: No homework | I34: =B34 -> 29 | J34: Unit 1 Game 1 & 2
B35: 30 | C35: REVIEW UNIT 2 | D35: 18-27 | E35: Review Unit 2 vocabulary - House and places - Numbers: 10-100 | F35: - Present continuous - Present simple: Talk about address - What's your address? It's 72 Station Road. | G35: Students review for the mid-term test | H35: No homework | I35: =B35 -> 30 | J35: Unit 2 Game 1 & 2
B36: 31 | C36: REVIEW UNIT 3 | D36: 28-35 | E36: Review Unit 3 vocabulary - Routines - Days of the week - Adverbs | F36: - What time does she wake up? She wakes up at seven o'clock. - What do you do before/after breakfast? How often do you....? I always/sometimes/never/...... | G36: Students review for the mid-term test | H36: No homework | I36: =B36 -> 31 | J36: Unit 3 Game 1 & 2
B37: 32 | C37: REVIEW UNIT 4 | D37: 36-43 | E37: Review Unit 4 vocabulary - Places in town - Preposition of place | F37: - Where is it? It's a... - What's opposite the cinema? It's the..... - Where is the ...? It's.... | G37: Students review for the mid-term test | H37: No homework | I37: =B37 -> 32 | J37: Unit 4 Game 1 & 2
B38: 33 | C38: TEST | D38: MIDTERM TEST | E38: MIDTERM TEST - LISTENING, READING, WRITING (For Listening, each part will be listened in 2 times) | G38: - Teachers instruct students what to do in each part of the paper test - Teachers prepare worksheets for students to do in class if they finish early - Teachers also can do speaking test for students while they're doing the worksheets | H38: No homework | I38: =B38 -> 33
B39: 34 | C39: TEST | D39: MIDTERM TEST | E39: MIDTERM TEST - SPEAKING (See the speaking instruction in Test Answer Key) | G39: - Teachers prepare worksheets for students to do in class - Teachers instruct students what to do in each part of the speaking test - Teachers complete the speaking test for all students | H39: No homework | I39: =B39 -> 34
B40: 35 | C40: YLE PRACTICE | D40: Link | E40: EXTRA BOOK: FUN FOR MOVERS (Unit 1-6) | G40: - Students practice Movers Cambridge exam - Teachers ask students to open Handbook | H40: No homework | I40: No homework
...

Sheet Trang tính2
B4: Grade | C4: Galax 3
B5: LESSONS | C5: 17
B6: UNITS | C6: =vlookup($C$5,'Sun 3'!B:J,2,0) -> UNIT 3 A DAY IN THE LIFE
B7: Student's book & Activity's book pages | C7: =vlookup($C$5,'Sun 3'!B:J,3,0) -> 28-29
B8: Vocabulary (Từ vựng) | C8: =vlookup($C$5,'Sun 3'!B:J,4,0) -> - Routines: get dressed/ undressed, get up, go to bed, have a shower, put on, wake up, take off, wash, catch the bus, do homework - Sing a song activity
B9: Structures (Cấu trúc) | C9: =vlookup($C$5,'Sun 3'!B:J,5,0) -> - What time does she wake up? She wakes up at seven o'clock. - What do you do before/after breakfast?
B10: Homework | C10: =vlookup($C$5,'Sun 3'!B:J,6,0) -> - Students understand the topic and remember the vocabulary. - Students can talk aout their daily routines. - Students can sing a song together.
